Workbook

Sheet Budget
A1: Weekly Income | E1: Monthy Expenses | J1: Credit Card Expenses | O1: Subscriptions
A2: Bill | B2: Amount | C2: DayOfMonth | E2: Bill | F2: Amount | G2: DayOfMonth | J2: Bill | K2: Amount | L2: Month | M2: DayOfMonth | O2: Bill | P2: Amount | Q2: DayOfYear
A3: PAY-LM | B3: 1453 | C3: 6 | E3: Rent | F3: =1682+12+7+20+12 -> 1733 | G3: 1 | H3: Extra: | J3: Capital One | K3: 467.61 | L3: 12 | M3: 7 | O3: Amazon Prime | P3: 7.48 | Q3: 8
E4: Car | F4: 503.35 | G4: 2 | H4: 0 | J4: Chase | K4: 406 | L4: 12 | M4: 4 | O4: YT Premium | P4: 22.99 | Q4: 9
E5: Mom Rent | F5: 850 | G5: 20 | J5: NFCU | K5: 72 | L5: 12 | M5: 6 | O5: Netflix | P5: 24.6 | Q5: 29
E6: Groceries | F6: =180+120 -> 300 | G6: 2 | J6: TOTAL | K6: =SUM(K3:K5) -> 945.61 | L6: - | M6: - | O6: Spotify | P6: 11.99 | Q6: 8
E7: Savings | F7: =1000 -> 1000 | G7: 28 | O7: Rocket Money | P7: 6 | Q7: 12
E8: AT&T | F8: 65 | G8: 18 | O8: Little4Much | P8: 150 | Q8: 28
E9: GA Power | F9: 70 | G9: 5 | O9: None
E10: TH | F10: =400 -> 400 | G10: 26 | O10: Subscriptions (Deactivated)
O11: Crunchyroll | P11: 8.53 | Q11: 27
E12: Annual Expenses | O12: Audible | P12: 0 | Q12: 11
E13: Bill | F13: Amount | G13: DayOfYear
E14: Car Insurance | F14: 1999.1 | G14: 45643
E15: Phone Bill | F15: 300 | G15: 45915

Sheet Detailed Monthy Sim
D1: Miscellaneous | E1: Monthly Expenses | N1: =Budget!$E$12 -> Annual Expenses | Q1: Credit Card | T1: Subscriptions | AA1: TOTAL | AC1: =SUMIF(D3:Z32,"<0") -> -6090.06 | AD1: =SUM(E3:E32) -> 5812
A2: 45658 | E2: =Budget!$A$3 -> PAY-LM | F2: =Budget!$E$3 -> Rent | G2: =Budget!$E$4 -> Car | H2: =Budget!$E$5 -> Mom Rent | I2: =Budget!$E$8 -> AT&T | J2: =Budget!$E$9 -> GA Power | K2: =Budget!$E$10 -> TH | L2: =Budget!$E$6 -> Groceries | M2: =Budget!$E$7 -> Savings | N2: =Budget!$E$14 -> Car Insurance | O2: =Budget!$E$15 -> Phone Bill | Q2: =Budget!$J$3 -> Capital One | R2: =Budget!$J$4 -> Chase | S2: =Budget!$J$5 -> NFCU | T2: =Budget!$O$3 -> Amazon Prime | U2: =Budget!$O$12 -> Audible | V2: =Budget!$O$5 -> Netflix | W2: =Budget!$O$6 -> Spotify | X2: =Budget!$O$7 -> Rocket Money | Y2: =Budget!$O$8 -> Little4Much | Z2: =Budget!$O$9 -> None | AC2: =AD1+AC1 -> -278.06
A3: =A2 -> 45658 | B3: 473.69 | C3: 0 | D3: 0 | E3: =N("PAY-LM")+IF(WEEKDAY(A3)=Budget!$C$3,Budget!$B$3,0) -> 0 | F3: =N("Rent")-IF(DAY(A3)=Budget!$G$3,Budget!$F$3,0) -> -1733 | G3: =N("Car")-IF(DAY(A3)=Budget!$G$4,Budget!$F$4+Budget!$H$4,0) -> 0 | H3: =N("Mom Rent")-IF(DAY(A3)=Budget!$G$5,Budget!$F$5,0) -> 0 | I3: =N("AT&T")-IF(DAY(A3)=Budget!$G$8,Budget!$F$8,0) -> 0 | J3: =N("GA Power")-IF(DAY(A3)=Budget!$G$9,Budget!$F$9,0) -> 0 | K3: =N("Haircut")-IF(DAY(A3)=Budget!$G$10,Budget!$F$10,0) -> 0 | L3: =N("Groceries")-IF(DAY(A3)=Budget!$G$6,Budget!$F$6,0) -> 0 | M3: =N("Savings")-IF(DAY(A3)=Budget!$G$7,Budget!$F$7,0) -> 0 | N3: =N("Car Insurance")-COUNTIF(Budget!$G$14,A3)*Budget!$F$14 -> 0 | O3: =N("Phone Bill")-COUNTIF(Budget!$G$15, A3)*Budget!$F$15 -> 0 | Q3: =N("Spotify")-IF(AND(DAY($A3)=Budget!$M$3, MONTH($A3)=Budget!$L$3),Budget!$K$3,0) -> 0 | R3: =N("Spotify")-IF(AND(DAY($A3)=Budget!$M$4, MONTH($A3)=Budget!$L$4),Budget!$K$4,0) -> 0 | S3: =N("Spotify")-IF(AND(DAY($A3)=Budget!$M$5, MONTH($A3)=Budget!$L$5),Budget!$K$5,0) -> 0 | T3: =N("Amazon Prime")-IF(DAY(A3)=Budget!$Q$3,Budget!$P$3,0) -> 0 | U3: =N("Audible")-IF(DAY(A3)=Budget!$Q$12,Budget!$P$12,0) -> 0 | V3: =N("Crunchyroll")-IF(DAY(A3)=Budget!$Q$5,Budget!$P$5,0) -> 0 | W3: =N("HBO Max")-IF(DAY(A3)=Budget!$Q$6,Budget!$P$6,0) -> 0 | X3: =N("Netflix")-IF(DAY(A3)=Budget!$Q$7,Budget!$P$7,0) -> 0 | Y3: =N("Spotify")-IF(DAY(A3)=Budget!$Q$8,Budget!$P$8,0) -> 0 | Z3: =N("Truebill")-IF(DAY(A3)=Budget!$Q$9,Budget!$P$9,0) -> 0 | AA3: =SUM(D3:Z3) -> -1733
A4: =A3+1 -> 45659 | B4: =B3+AA4 -> -329.66 | C4: =IF(B4>B3,2,IF(B4=B3, 1,0)) -> 0 | D4: 0 | E4: =N("PAY-LM")+IF(WEEKDAY(A4)=Budget!$C$3,Budget!$B$3,0) -> 0 | F4: =N("Rent")-IF(DAY(A4)=Budget!$G$3,Budget!$F$3,0) -> 0 | G4: =N("Car")-IF(DAY(A4)=Budget!$G$4,Budget!$F$4+Budget!$H$4,0) -> -503.35 | H4: =N("Mom Rent")-IF(DAY(A4)=Budget!$G$5,Budget!$F$5,0) -> 0 | I4: =N("AT&T")-IF(DAY(A4)=Budget!$G$8,Budget!$F$8,0) -> 0 | J4: =N("GA Power")-IF(DAY(A4)=Budget!$G$9,Budget!$F$9,0) -> 0 | K4: =N("Haircut")-IF(DAY(A4)=Budget!$G$10,Budget!$F$10,0) -> 0 | L4: =N("Groceries")-IF(DAY(A4)=Budget!$G$6,Budget!$F$6,0) -> -300 | M4: =N("Savings")-IF(DAY(A4)=Budget!$G$7,Budget!$F$7,0) -> 0 | N4: =N("Car Insurance")-COUNTIF(Budget!$G$14,A4)*Budget!$F$14 -> 0 | O4: =N("Phone Bill")-COUNTIF(Budget!$G$15, A4)*Budget!$F$15 -> 0 | Q4: =N("Spotify")-IF(AND(DAY($A4)=Budget!$M$3, MONTH($A4)=Budget!$L$3),Budget!$K$3,0) -> 0 | R4: =N("Spotify")-IF(AND(DAY($A4)=Budget!$M$4, MONTH($A4)=Budget!$L$4),Budget!$K$4,0) -> 0 | S4: =N("Spotify")-IF(AND(DAY($A4)=Budget!$M$5, MONTH($A4)=Budget!$L$5),Budget!$K$5,0) -> 0 | T4: =N("Amazon Prime")-IF(DAY(A4)=Budget!$Q$3,Budget!$P$3,0) -> 0 | U4: =N("Audible")-IF(DAY(A4)=Budget!$Q$12,Budget!$P$12,0) -> 0 | V4: =N("Crunchyroll")-IF(DAY(A4)=Budget!$Q$5,Budget!$P$5,0) -> 0 | W4: =N("HBO Max")-IF(DAY(A4)=Budget!$Q$6,Budget!$P$6,0) -> 0 | X4: =N("Netflix")-IF(DAY(A4)=Budget!$Q$7,Budget!$P$7,0) -> 0 | Y4: =N("Spotify")-IF(DAY(A4)=Budget!$Q$8,Budget!$P$8,0) -> 0 | Z4: =N("Truebill")-IF(DAY(A4)=Budget!$Q$9,Budget!$P$9,0) -> 0 | AA4: =SUM(D4:Z4) -> -803.35
A5: =A4+1 -> 45660 | B5: =B4+AA5 -> 1123.34 | C5: =IF(B5>B4,2,IF(B5=B4, 1,0)) -> 2 | D5: 0 | E5: =N("PAY-LM")+IF(WEEKDAY(A5)=Budget!$C$3,Budget!$B$3,0) -> 1453 | F5: =N("Rent")-IF(DAY(A5)=Budget!$G$3,Budget!$F$3,0) -> 0 | G5: =N("Car")-IF(DAY(A5)=Budget!$G$4,Budget!$F$4+Budget!$H$4,0) -> 0 | H5: =N("Mom Rent")-IF(DAY(A5)=Budget!$G$5,Budget!$F$5,0) -> 0 | I5: =N("AT&T")-IF(DAY(A5)=Budget!$G$8,Budget!$F$8,0) -> 0 | J5: =N("GA Power")-IF(DAY(A5)=Budget!$G$9,Budget!$F$9,0) -> 0 | K5: =N("Haircut")-IF(DAY(A5)=Budget!$G$10,Budget!$F$10,0) -> 0 | L5: =N("Groceries")-IF(DAY(A5)=Budget!$G$6,Budget!$F$6,0) -> 0 | M5: =N("Savings")-IF(DAY(A5)=Budget!$G$7,Budget!$F$7,0) -> 0 | N5: =N("Car Insurance")-COUNTIF(Budget!$G$14,A5)*Budget!$F$14 -> 0 | O5: =N("Phone Bill")-COUNTIF(Budget!$G$15, A5)*Budget!$F$15 -> 0 | Q5: =N("Spotify")-IF(AND(DAY($A5)=Budget!$M$3, MONTH($A5)=Budget!$L$3),Budget!$K$3,0) -> 0 | R5: =N("Spotify")-IF(AND(DAY($A5)=Budget!$M$4, MONTH($A5)=Budget!$L$4),Budget!$K$4,0) -> 0 | S5: =N("Spotify")-IF(AND(DAY($A5)=Budget!$M$5, MONTH($A5)=Budget!$L$5),Budget!$K$5,0) -> 0 | T5: =N("Amazon Prime")-IF(DAY(A5)=Budget!$Q$3,Budget!$P$3,0) -> 0 | U5: =N("Audible")-IF(DAY(A5)=Budget!$Q$12,Budget!$P$12,0) -> 0 | V5: =N("Crunchyroll")-IF(DAY(A5)=Budget!$Q$5,Budget!$P$5,0) -> 0 | W5: =N("HBO Max")-IF(DAY(A5)=Budget!$Q$6,Budget!$P$6,0) -> 0 | X5: =N("Netflix")-IF(DAY(A5)=Budget!$Q$7,Budget!$P$7,0) -> 0 | Y5: =N("Spotify")-IF(DAY(A5)=Budget!$Q$8,Budget!$P$8,0) -> 0 | Z5: =N("Truebill")-IF(DAY(A5)=Budget!$Q$9,Budget!$P$9,0) -> 0 | AA5: =SUM(D5:Z5) -> 1453
A6: =A5+1 -> 45661 | B6: =B5+AA6 -> 686.27 | C6: =IF(B6>B5,2,IF(B6=B5, 1,0)) -> 0 | D6: 0 | E6: =N("PAY-LM")+IF(WEEKDAY(A6)=Budget!$C$3,Budget!$B$3,0) -> 0 | F6: =N("Rent")-IF(DAY(A6)=Budget!$G$3,Budget!$F$3,0) -> 0 | G6: =N("Car")-IF(DAY(A6)=Budget!$G$4,Budget!$F$4+Budget!$H$4,0) -> 0 | H6: =N("Mom Rent")-IF(DAY(A6)=Budget!$G$5,Budget!$F$5,0) -> 0 | I6: =N("AT&T")-IF(DAY(A6)=Budget!$G$8,Budget!$F$8,0) -> 0 | J6: =N("GA Power")-IF(DAY(A6)=Budget!$G$9,Budget!$F$9,0) -> 0 | K6: =N("Haircut")-IF(DAY(A6)=Budget!$G$10,Budget!$F$10,0) -> 0 | L6: =N("Groceries")-IF(DAY(A6)=Budget!$G$6,Budget!$F$6,0) -> 0 | M6: =N("Savings")-IF(DAY(A6)=Budget!$G$7,Budget!$F$7,0) -> 0 | N6: =N("Car Insurance")-COUNTIF(Budget!$G$14,A6)*Budget!$F$14 -> 0 | O6: =N("Phone Bill")-COUNTIF(Budget!$G$15, A6)*Budget!$F$15 -> 0 | Q6: =N("Spotify")-IF(AND(DAY($A6)=Budget!$M$3, MONTH($A6)=Budget!$L$3),Budget!$K$3,0) -> 0 | R6: -437.07 | S6: =N("Spotify")-IF(AND(DAY($A6)=Budget!$M$5, MONTH($A6)=Budget!$L$5),Budget!$K$5,0) -> 0 | T6: =N("Amazon Prime")-IF(DAY(A6)=Budget!$Q$3,Budget!$P$3,0) -> 0 | U6: =N("Audible")-IF(DAY(A6)=Budget!$Q$12,Budget!$P$12,0) -> 0 | V6: =N("Crunchyroll")-IF(DAY(A6)=Budget!$Q$5,Budget!$P$5,0) -> 0 | W6: =N("HBO Max")-IF(DAY(A6)=Budget!$Q$6,Budget!$P$6,0) -> 0 | X6: =N("Netflix")-IF(DAY(A6)=Budget!$Q$7,Budget!$P$7,0) -> 0 | Y6: =N("Spotify")-IF(DAY(A6)=Budget!$Q$8,Budget!$P$8,0) -> 0 | Z6: =N("Truebill")-IF(DAY(A6)=Budget!$Q$9,Budget!$P$9,0) -> 0 | AA6: =SUM(D6:Z6) -> -437.07
A7: =A6+1 -> 45662 | B7: =1519.79 -> 1519.79 | C7: =IF(B7>B6,2,IF(B7=B6, 1,0)) -> 2 | D7: 0 | E7: =N("PAY-LM")+IF(WEEKDAY(A7)=Budget!$C$3,Budget!$B$3,0) -> 0 | F7: =N("Rent")-IF(DAY(A7)=Budget!$G$3,Budget!$F$3,0) -> 0 | G7: =N("Car")-IF(DAY(A7)=Budget!$G$4,Budget!$F$4+Budget!$H$4,0) -> 0 | H7: =N("Mom Rent")-IF(DAY(A7)=Budget!$G$5,Budget!$F$5,0) -> 0 | I7: =N("AT&T")-IF(DAY(A7)=Budget!$G$8,Budget!$F$8,0) -> 0 | J7: =N("GA Power")-IF(DAY(A7)=Budget!$G$9,Budget!$F$9,0) -> -70 | K7: =N("Haircut")-IF(DAY(A7)=Budget!$G$10,Budget!$F$10,0) -> 0 | L7: =N("Groceries")-IF(DAY(A7)=Budget!$G$6,Budget!$F$6,0) -> 0 | M7: =N("Savings")-IF(DAY(A7)=Budget!$G$7,Budget!$F$7,0) -> 0 | N7: =N("Car Insurance")-COUNTIF(Budget!$G$14,A7)*Budget!$F$14 -> 0 | O7: =N("Phone Bill")-COUNTIF(Budget!$G$15, A7)*Budget!$F$15 -> 0 | Q7: =N("Spotify")-IF(AND(DAY($A7)=Budget!$M$3, MONTH($A7)=Budget!$L$3),Budget!$K$3,0) -> 0 | R7: =N("Spotify")-IF(AND(DAY($A7)=Budget!$M$4, MONTH($A7)=Budget!$L$4),Budget!$K$4,0) -> 0 | S7: =N("Spotify")-IF(AND(DAY($A7)=Budget!$M$5, MONTH($A7)=Budget!$L$5),Budget!$K$5,0) -> 0 | T7: =N("Amazon Prime")-IF(DAY(A7)=Budget!$Q$3,Budget!$P$3,0) -> 0 | U7: =N("Audible")-IF(DAY(A7)=Budget!$Q$12,Budget!$P$12,0) -> 0 | V7: =N("Crunchyroll")-IF(DAY(A7)=Budget!$Q$5,Budget!$P$5,0) -> 0 | W7: =N("HBO Max")-IF(DAY(A7)=Budget!$Q$6,Budget!$P$6,0) -> 0 | X7: =N("Netflix")-IF(DAY(A7)=Budget!$Q$7,Budget!$P$7,0) -> 0 | Y7: =N("Spotify")-IF(DAY(A7)=Budget!$Q$8,Budget!$P$8,0) -> 0 | Z7: =N("Truebill")-IF(DAY(A7)=Budget!$Q$9,Budget!$P$9,0) -> 0 | AA7: =SUM(D7:Z7) -> -70
A8: =A7+1 -> 45663 | B8: =1082.72 -> 1082.72 | C8: =IF(B8>B7,2,IF(B8=B7, 1,0)) -> 0 | D8: 0 | E8: =N("PAY-LM")+IF(WEEKDAY(A8)=Budget!$C$3,Budget!$B$3,0) -> 0 | F8: =N("Rent")-IF(DAY(A8)=Budget!$G$3,Budget!$F$3,0) -> 0 | G8: =N("Car")-IF(DAY(A8)=Budget!$G$4,Budget!$F$4+Budget!$H$4,0) -> 0 | H8: =N("Mom Rent")-IF(DAY(A8)=Budget!$G$5,Budget!$F$5,0) -> 0 | I8: =N("AT&T")-IF(DAY(A8)=Budget!$G$8,Budget!$F$8,0) -> 0 | J8: =N("GA Power")-IF(DAY(A8)=Budget!$G$9,Budget!$F$9,0) -> 0 | K8: =N("Haircut")-IF(DAY(A8)=Budget!$G$10,Budget!$F$10,0) -> 0 | L8: =N("Groceries")-IF(DAY(A8)=Budget!$G$6,Budget!$F$6,0) -> 0 | M8: =N("Savings")-IF(DAY(A8)=Budget!$G$7,Budget!$F$7,0) -> 0 | N8: =N("Car Insurance")-COUNTIF(Budget!$G$14,A8)*Budget!$F$14 -> 0 | O8: =N("Phone Bill")-COUNTIF(Budget!$G$15, A8)*Budget!$F$15 -> 0 | Q8: =N("Spotify")-IF(AND(DAY($A8)=Budget!$M$3, MONTH($A8)=Budget!$L$3),Budget!$K$3,0) -> 0 | R8: =N("Spotify")-IF(AND(DAY($A8)=Budget!$M$4, MONTH($A8)=Budget!$L$4),Budget!$K$4,0) -> 0 | S8: -49.57 | T8: =N("Amazon Prime")-IF(DAY(A8)=Budget!$Q$3,Budget!$P$3,0) -> 0 | U8: =N("Audible")-IF(DAY(A8)=Budget!$Q$12,Budget!$P$12,0) -> 0 | V8: =N("Crunchyroll")-IF(DAY(A8)=Budget!$Q$5,Budget!$P$5,0) -> 0 | W8: =N("HBO Max")-IF(DAY(A8)=Budget!$Q$6,Budget!$P$6,0) -> 0 | X8: =N("Netflix")-IF(DAY(A8)=Budget!$Q$7,Budget!$P$7,0) -> 0 | Y8: =N("Spotify")-IF(DAY(A8)=Budget!$Q$8,Budget!$P$8,0) -> 0 | Z8: =N("Truebill")-IF(DAY(A8)=Budget!$Q$9,Budget!$P$9,0) -> 0 | AA8: =SUM(D8:Z8) -> -49.57
A9: =A8+1 -> 45664 | B9: =B8+AA9 -> 710.72 | C9: =IF(B9>B8,2,IF(B9=B8, 1,0)) -> 0 | D9: =-172-200 -> -372 | E9: =N("PAY-LM")+IF(WEEKDAY(A9)=Budget!$C$3,Budget!$B$3,0) -> 0 | F9: =N("Rent")-IF(DAY(A9)=Budget!$G$3,Budget!$F$3,0) -> 0 | G9: =N("Car")-IF(DAY(A9)=Budget!$G$4,Budget!$F$4+Budget!$H$4,0) -> 0 | H9: =N("Mom Rent")-IF(DAY(A9)=Budget!$G$5,Budget!$F$5,0) -> 0 | I9: =N("AT&T")-IF(DAY(A9)=Budget!$G$8,Budget!$F$8,0) -> 0 | J9: =N("GA Power")-IF(DAY(A9)=Budget!$G$9,Budget!$F$9,0) -> 0 | K9: =N("Haircut")-IF(DAY(A9)=Budget!$G$10,Budget!$F$10,0) -> 0 | L9: =N("Groceries")-IF(DAY(A9)=Budget!$G$6,Budget!$F$6,0) -> 0 | M9: =N("Savings")-IF(DAY(A9)=Budget!$G$7,Budget!$F$7,0) -> 0 | N9: =N("Car Insurance")-COUNTIF(Budget!$G$14,A9)*Budget!$F$14 -> 0 | O9: =N("Phone Bill")-COUNTIF(Budget!$G$15, A9)*Budget!$F$15 -> 0 | Q9: =N("Spotify")-IF(AND(DAY($A9)=Budget!$M$3, MONTH($A9)=Budget!$L$3),Budget!$K$3,0) -> 0 | R9: =N("Spotify")-IF(AND(DAY($A9)=Budget!$M$4, MONTH($A9)=Budget!$L$4),Budget!$K$4,0) -> 0 | S9: =N("Spotify")-IF(AND(DAY($A9)=Budget!$M$5, MONTH($A9)=Budget!$L$5),Budget!$K$5,0) -> 0 | T9: =N("Amazon Prime")-IF(DAY(A9)=Budget!$Q$3,Budget!$P$3,0) -> 0 | U9: =N("Audible")-IF(DAY(A9)=Budget!$Q$12,Budget!$P$12,0) -> 0 | V9: =N("Crunchyroll")-IF(DAY(A9)=Budget!$Q$5,Budget!$P$5,0) -> 0 | W9: =N("HBO Max")-IF(DAY(A9)=Budget!$Q$6,Budget!$P$6,0) -> 0 | X9: =N("Netflix")-IF(DAY(A9)=Budget!$Q$7,Budget!$P$7,0) -> 0 | Y9: =N("Spotify")-IF(DAY(A9)=Budget!$Q$8,Budget!$P$8,0) -> 0 | Z9: =N("Truebill")-IF(DAY(A9)=Budget!$Q$9,Budget!$P$9,0) -> 0 | AA9: =SUM(D9:Z9) -> -372
A10: =A9+1 -> 45665 | B10: =B9+AA10 -> 581.25 | C10: =IF(B10>B9,2,IF(B10=B9, 1,0)) -> 0 | D10: -110 | E10: =N("PAY-LM")+IF(WEEKDAY(A10)=Budget!$C$3,Budget!$B$3,0) -> 0 | F10: =N("Rent")-IF(DAY(A10)=Budget!$G$3,Budget!$F$3,0) -> 0 | G10: =N("Car")-IF(DAY(A10)=Budget!$G$4,Budget!$F$4+Budget!$H$4,0) -> 0 | H10: =N("Mom Rent")-IF(DAY(A10)=Budget!$G$5,Budget!$F$5,0) -> 0 | I10: =N("AT&T")-IF(DAY(A10)=Budget!$G$8,Budget!$F$8,0) -> 0 | J10: =N("GA Power")-IF(DAY(A10)=Budget!$G$9,Budget!$F$9,0) -> 0 | K10: =N("Haircut")-IF(DAY(A10)=Budget!$G$10,Budget!$F$10,0) -> 0 | L10: =N("Groceries")-IF(DAY(A10)=Budget!$G$6,Budget!$F$6,0) -> 0 | M10: =N("Savings")-IF(DAY(A10)=Budget!$G$7,Budget!$F$7,0) -> 0 | N10: =N("Car Insurance")-COUNTIF(Budget!$G$14,A10)*Budget!$F$14 -> 0 | O10: =N("Phone Bill")-COUNTIF(Budget!$G$15, A10)*Budget!$F$15 -> 0 | Q10: =N("Spotify")-IF(AND(DAY($A10)=Budget!$M$3, MONTH($A10)=Budget!$L$3),Budget!$K$3,0) -> 0 | R10: =N("Spotify")-IF(AND(DAY($A10)=Budget!$M$4, MONTH($A10)=Budget!$L$4),Budget!$K$4,0) -> 0 | S10: =N("Spotify")-IF(AND(DAY($A10)=Budget!$M$5, MONTH($A10)=Budget!$L$5),Budget!$K$5,0) -> 0 | T10: =N("Amazon Prime")-IF(DAY(A10)=Budget!$Q$3,Budget!$P$3,0) -> -7.48 | U10: =N("Audible")-IF(DAY(A10)=Budget!$Q$12,Budget!$P$12,0) -> 0 | V10: =N("Crunchyroll")-IF(DAY(A10)=Budget!$Q$5,Budget!$P$5,0) -> 0 | W10: =N("HBO Max")-IF(DAY(A10)=Budget!$Q$6,Budget!$P$6,0) -> -11.99 | X10: =N("Netflix")-IF(DAY(A10)=Budget!$Q$7,Budget!$P$7,0) -> 0 | Y10: =N("Spotify")-IF(DAY(A10)=Budget!$Q$8,Budget!$P$8,0) -> 0 | Z10: =N("Truebill")-IF(DAY(A10)=Budget!$Q$9,Budget!$P$9,0) -> 0 | AA10: =SUM(D10:Z10) -> -129.47
A11: =A10+1 -> 45666 | B11: =B10+AA11 -> 581.25 | C11: =IF(B11>B10,2,IF(B11=B10, 1,0)) -> 1 | D11: 0 | E11: =N("PAY-LM")+IF(WEEKDAY(A11)=Budget!$C$3,Budget!$B$3,0) -> 0 | F11: =N("Rent")-IF(DAY(A11)=Budget!$G$3,Budget!$F$3,0) -> 0 | G11: =N("Car")-IF(DAY(A11)=Budget!$G$4,Budget!$F$4+Budget!$H$4,0) -> 0 | H11: =N("Mom Rent")-IF(DAY(A11)=Budget!$G$5,Budget!$F$5,0) -> 0 | I11: =N("AT&T")-IF(DAY(A11)=Budget!$G$8,Budget!$F$8,0) -> 0 | J11: =N("GA Power")-IF(DAY(A11)=Budget!$G$9,Budget!$F$9,0) -> 0 | K11: =N("Haircut")-IF(DAY(A11)=Budget!$G$10,Budget!$F$10,0) -> 0 | L11: =N("Groceries")-IF(DAY(A11)=Budget!$G$6,Budget!$F$6,0) -> 0 | M11: =N("Savings")-IF(DAY(A11)=Budget!$G$7,Budget!$F$7,0) -> 0 | N11: =N("Car Insurance")-COUNTIF(Budget!$G$14,A11)*Budget!$F$14 -> 0 | O11: =N("Phone Bill")-COUNTIF(Budget!$G$15, A11)*Budget!$F$15 -> 0 | Q11: =N("Spotify")-IF(AND(DAY($A11)=Budget!$M$3, MONTH($A11)=Budget!$L$3),Budget!$K$3,0) -> 0 | R11: =N("Spotify")-IF(AND(DAY($A11)=Budget!$M$4, MONTH($A11)=Budget!$L$4),Budget!$K$4,0) -> 0 | S11: =N("Spotify")-IF(AND(DAY($A11)=Budget!$M$5, MONTH($A11)=Budget!$L$5),Budget!$K$5,0) -> 0 | T11: =N("Amazon Prime")-IF(DAY(A11)=Budget!$Q$3,Budget!$P$3,0) -> 0 | U11: =N("Audible")-IF(DAY(A11)=Budget!$Q$12,Budget!$P$12,0) -> 0 | V11: =N("Crunchyroll")-IF(DAY(A11)=Budget!$Q$5,Budget!$P$5,0) -> 0 | W11: =N("HBO Max")-IF(DAY(A11)=Budget!$Q$6,Budget!$P$6,0) -> 0 | X11: =N("Netflix")-IF(DAY(A11)=Budget!$Q$7,Budget!$P$7,0) -> 0 | Y11: =N("Spotify")-IF(DAY(A11)=Budget!$Q$8,Budget!$P$8,0) -> 0 | Z11: =N("Truebill")-IF(DAY(A11)=Budget!$Q$9,Budget!$P$9,0) -> 0 | AA11: =SUM(D11:Z11) -> 0
A12: =A11+1 -> 45667 | B12: =B11+AA12 -> 2034.25 | C12: =IF(B12>B11,2,IF(B12=B11, 1,0)) -> 2 | D12: 0 | E12: =N("PAY-LM")+IF(WEEKDAY(A12)=Budget!$C$3,Budget!$B$3,0) -> 1453 | F12: =N("Rent")-IF(DAY(A12)=Budget!$G$3,Budget!$F$3,0) -> 0 | G12: =N("Car")-IF(DAY(A12)=Budget!$G$4,Budget!$F$4+Budget!$H$4,0) -> 0 | H12: =N("Mom Rent")-IF(DAY(A12)=Budget!$G$5,Budget!$F$5,0) -> 0 | I12: =N("AT&T")-IF(DAY(A12)=Budget!$G$8,Budget!$F$8,0) -> 0 | J12: =N("GA Power")-IF(DAY(A12)=Budget!$G$9,Budget!$F$9,0) -> 0 | K12: =N("Haircut")-IF(DAY(A12)=Budget!$G$10,Budget!$F$10,0) -> 0 | L12: =N("Groceries")-IF(DAY(A12)=Budget!$G$6,Budget!$F$6,0) -> 0 | M12: =N("Savings")-IF(DAY(A12)=Budget!$G$7,Budget!$F$7,0) -> 0 | N12: =N("Car Insurance")-COUNTIF(Budget!$G$14,A12)*Budget!$F$14 -> 0 | O12: =N("Phone Bill")-COUNTIF(Budget!$G$15, A12)*Budget!$F$15 -> 0 | Q12: =N("Spotify")-IF(AND(DAY($A12)=Budget!$M$3, MONTH($A12)=Budget!$L$3),Budget!$K$3,0) -> 0 | R12: =N("Spotify")-IF(AND(DAY($A12)=Budget!$M$4, MONTH($A12)=Budget!$L$4),Budget!$K$4,0) -> 0 | S12: =N("Spotify")-IF(AND(DAY($A12)=Budget!$M$5, MONTH($A12)=Budget!$L$5),Budget!$K$5,0) -> 0 | T12: =N("Amazon Prime")-IF(DAY(A12)=Budget!$Q$3,Budget!$P$3,0) -> 0 | U12: =N("Audible")-IF(DAY(A12)=Budget!$Q$12,Budget!$P$12,0) -> 0 | V12: =N("Crunchyroll")-IF(DAY(A12)=Budget!$Q$5,Budget!$P$5,0) -> 0 | W12: =N("HBO Max")-IF(DAY(A12)=Budget!$Q$6,Budget!$P$6,0) -> 0 | X12: =N("Netflix")-IF(DAY(A12)=Budget!$Q$7,Budget!$P$7,0) -> 0 | Y12: =N("Spotify")-IF(DAY(A12)=Budget!$Q$8,Budget!$P$8,0) -> 0 | Z12: =N("Truebill")-IF(DAY(A12)=Budget!$Q$9,Budget!$P$9,0) -> 0 | AA12: =SUM(D12:Z12) -> 1453
A13: =A12+1 -> 45668 | B13: =B12+AA13 -> 2034.25 | C13: =IF(B13>B12,2,IF(B13=B12, 1,0)) -> 1 | D13: 0 | E13: =N("PAY-LM")+IF(WEEKDAY(A13)=Budget!$C$3,Budget!$B$3,0) -> 0 | F13: =N("Rent")-IF(DAY(A13)=Budget!$G$3,Budget!$F$3,0) -> 0 | G13: =N("Car")-IF(DAY(A13)=Budget!$G$4,Budget!$F$4+Budget!$H$4,0) -> 0 | H13: =N("Mom Rent")-IF(DAY(A13)=Budget!$G$5,Budget!$F$5,0) -> 0 | I13: =N("AT&T")-IF(DAY(A13)=Budget!$G$8,Budget!$F$8,0) -> 0 | J13: =N("GA Power")-IF(DAY(A13)=Budget!$G$9,Budget!$F$9,0) -> 0 | K13: =N("Haircut")-IF(DAY(A13)=Budget!$G$10,Budget!$F$10,0) -> 0 | L13: =N("Groceries")-IF(DAY(A13)=Budget!$G$6,Budget!$F$6,0) -> 0 | M13: =N("Savings")-IF(DAY(A13)=Budget!$G$7,Budget!$F$7,0) -> 0 | N13: =N("Car Insurance")-COUNTIF(Budget!$G$14,A13)*Budget!$F$14 -> 0 | O13: =N("Phone Bill")-COUNTIF(Budget!$G$15, A13)*Budget!$F$15 -> 0 | Q13: =N("Spotify")-IF(AND(DAY($A13)=Budget!$M$3, MONTH($A13)=Budget!$L$3),Budget!$K$3,0) -> 0 | R13: =N("Spotify")-IF(AND(DAY($A13)=Budget!$M$4, MONTH($A13)=Budget!$L$4),Budget!$K$4,0) -> 0 | S13: =N("Spotify")-IF(AND(DAY($A13)=Budget!$M$5, MONTH($A13)=Budget!$L$5),Budget!$K$5,0) -> 0 | T13: =N("Amazon Prime")-IF(DAY(A13)=Budget!$Q$3,Budget!$P$3,0) -> 0 | U13: =N("Audible")-IF(DAY(A13)=Budget!$Q$12,Budget!$P$12,0) -> 0 | V13: =N("Crunchyroll")-IF(DAY(A13)=Budget!$Q$5,Budget!$P$5,0) -> 0 | W13: =N("HBO Max")-IF(DAY(A13)=Budget!$Q$6,Budget!$P$6,0) -> 0 | X13: =N("Netflix")-IF(DAY(A13)=Budget!$Q$7,Budget!$P$7,0) -> 0 | Y13: =N("Spotify")-IF(DAY(A13)=Budget!$Q$8,Budget!$P$8,0) -> 0 | Z13: =N("Truebill")-IF(DAY(A13)=Budget!$Q$9,Budget!$P$9,0) -> 0 | AA13: =SUM(D13:Z13) -> 0
A14: =A13+1 -> 45669 | B14: =B13+AA14 -> 2028.25 | C14: =IF(B14>B13,2,IF(B14=B13, 1,0)) -> 0 | D14: 0 | E14: =N("PAY-LM")+IF(WEEKDAY(A14)=Budget!$C$3,Budget!$B$3,0) -> 0 | F14: =N("Rent")-IF(DAY(A14)=Budget!$G$3,Budget!$F$3,0) -> 0 | G14: =N("Car")-IF(DAY(A14)=Budget!$G$4,Budget!$F$4+Budget!$H$4,0) -> 0 | H14: =N("Mom Rent")-IF(DAY(A14)=Budget!$G$5,Budget!$F$5,0) -> 0 | I14: =N("AT&T")-IF(DAY(A14)=Budget!$G$8,Budget!$F$8,0) -> 0 | J14: =N("GA Power")-IF(DAY(A14)=Budget!$G$9,Budget!$F$9,0) -> 0 | K14: =N("Haircut")-IF(DAY(A14)=Budget!$G$10,Budget!$F$10,0) -> 0 | L14: =N("Groceries")-IF(DAY(A14)=Budget!$G$6,Budget!$F$6,0) -> 0 | M14: =N("Savings")-IF(DAY(A14)=Budget!$G$7,Budget!$F$7,0) -> 0 | N14: =N("Car Insurance")-COUNTIF(Budget!$G$14,A14)*Budget!$F$14 -> 0 | O14: =N("Phone Bill")-COUNTIF(Budget!$G$15, A14)*Budget!$F$15 -> 0 | Q14: =N("Spotify")-IF(AND(DAY($A14)=Budget!$M$3, MONTH($A14)=Budget!$L$3),Budget!$K$3,0) -> 0 | R14: =N("Spotify")-IF(AND(DAY($A14)=Budget!$M$4, MONTH($A14)=Budget!$L$4),Budget!$K$4,0) -> 0 | S14: =N("Spotify")-IF(AND(DAY($A14)=Budget!$M$5, MONTH($A14)=Budget!$L$5),Budget!$K$5,0) -> 0 | T14: =N("Amazon Prime")-IF(DAY(A14)=Budget!$Q$3,Budget!$P$3,0) -> 0 | U14: =N("Audible")-IF(DAY(A14)=Budget!$Q$12,Budget!$P$12,0) -> 0 | V14: =N("Crunchyroll")-IF(DAY(A14)=Budget!$Q$5,Budget!$P$5,0) -> 0 | W14: =N("HBO Max")-IF(DAY(A14)=Budget!$Q$6,Budget!$P$6,0) -> 0 | X14: =N("Netflix")-IF(DAY(A14)=Budget!$Q$7,Budget!$P$7,0) -> -6 | Y14: =N("Spotify")-IF(DAY(A14)=Budget!$Q$8,Budget!$P$8,0) -> 0 | Z14: =N("Truebill")-IF(DAY(A14)=Budget!$Q$9,Budget!$P$9,0) -> 0 | AA14: =SUM(D14:Z14) -> -6
A15: =A14+1 -> 45670 | B15: =B14+AA15 -> 2028.25 | C15: =IF(B15>B14,2,IF(B15=B14, 1,0)) -> 1 | D15: 0 | E15: =N("PAY-LM")+IF(WEEKDAY(A15)=Budget!$C$3,Budget!$B$3,0) -> 0 | F15: =N("Rent")-IF(DAY(A15)=Budget!$G$3,Budget!$F$3,0) -> 0 | G15: =N("Car")-IF(DAY(A15)=Budget!$G$4,Budget!$F$4+Budget!$H$4,0) -> 0 | H15: =N("Mom Rent")-IF(DAY(A15)=Budget!$G$5,Budget!$F$5,0) -> 0 | I15: =N("AT&T")-IF(DAY(A15)=Budget!$G$8,Budget!$F$8,0) -> 0 | J15: =N("GA Power")-IF(DAY(A15)=Budget!$G$9,Budget!$F$9,0) -> 0 | K15: =N("Haircut")-IF(DAY(A15)=Budget!$G$10,Budget!$F$10,0) -> 0 | L15: =N("Groceries")-IF(DAY(A15)=Budget!$G$6,Budget!$F$6,0) -> 0 | M15: =N("Savings")-IF(DAY(A15)=Budget!$G$7,Budget!$F$7,0) -> 0 | N15: =N("Car Insurance")-COUNTIF(Budget!$G$14,A15)*Budget!$F$14 -> 0 | O15: =N("Phone Bill")-COUNTIF(Budget!$G$15, A15)*Budget!$F$15 -> 0 | Q15: =N("Spotify")-IF(AND(DAY($A15)=Budget!$M$3, MONTH($A15)=Budget!$L$3),Budget!$K$3,0) -> 0 | R15: =N("Spotify")-IF(AND(DAY($A15)=Budget!$M$4, MONTH($A15)=Budget!$L$4),Budget!$K$4,0) -> 0 | S15: =N("Spotify")-IF(AND(DAY($A15)=Budget!$M$5, MONTH($A15)=Budget!$L$5),Budget!$K$5,0) -> 0 | T15: =N("Amazon Prime")-IF(DAY(A15)=Budget!$Q$3,Budget!$P$3,0) -> 0 | U15: =N("Audible")-IF(DAY(A15)=Budget!$Q$12,Budget!$P$12,0) -> 0 | V15: =N("Crunchyroll")-IF(DAY(A15)=Budget!$Q$5,Budget!$P$5,0) -> 0 | W15: =N("HBO Max")-IF(DAY(A15)=Budget!$Q$6,Budget!$P$6,0) -> 0 | X15: =N("Netflix")-IF(DAY(A15)=Budget!$Q$7,Budget!$P$7,0) -> 0 | Y15: =N("Spotify")-IF(DAY(A15)=Budget!$Q$8,Budget!$P$8,0) -> 0 | Z15: =N("Truebill")-IF(DAY(A15)=Budget!$Q$9,Budget!$P$9,0) -> 0 | AA15: =SUM(D15:Z15) -> 0
A16: =A15+1 -> 45671 | B16: =B15+AA16 -> 2028.25 | C16: =IF(B16>B15,2,IF(B16=B15, 1,0)) -> 1 | D16: 0 | E16: =N("PAY-LM")+IF(WEEKDAY(A16)=Budget!$C$3,Budget!$B$3,0) -> 0 | F16: =N("Rent")-IF(DAY(A16)=Budget!$G$3,Budget!$F$3,0) -> 0 | G16: =N("Car")-IF(DAY(A16)=Budget!$G$4,Budget!$F$4+Budget!$H$4,0) -> 0 | H16: =N("Mom Rent")-IF(DAY(A16)=Budget!$G$5,Budget!$F$5,0) -> 0 | I16: =N("AT&T")-IF(DAY(A16)=Budget!$G$8,Budget!$F$8,0) -> 0 | J16: =N("GA Power")-IF(DAY(A16)=Budget!$G$9,Budget!$F$9,0) -> 0 | K16: =N("Haircut")-IF(DAY(A16)=Budget!$G$10,Budget!$F$10,0) -> 0 | L16: =N("Groceries")-IF(DAY(A16)=Budget!$G$6,Budget!$F$6,0) -> 0 | M16: =N("Savings")-IF(DAY(A16)=Budget!$G$7,Budget!$F$7,0) -> 0 | N16: =N("Car Insurance")-COUNTIF(Budget!$G$14,A16)*Budget!$F$14 -> 0 | O16: =N("Phone Bill")-COUNTIF(Budget!$G$15, A16)*Budget!$F$15 -> 0 | Q16: =N("Spotify")-IF(AND(DAY($A16)=Budget!$M$3, MONTH($A16)=Budget!$L$3),Budget!$K$3,0) -> 0 | R16: =N("Spotify")-IF(AND(DAY($A16)=Budget!$M$4, MONTH($A16)=Budget!$L$4),Budget!$K$4,0) -> 0 | S16: =N("Spotify")-IF(AND(DAY($A16)=Budget!$M$5, MONTH($A16)=Budget!$L$5),Budget!$K$5,0) -> 0 | T16: =N("Amazon Prime")-IF(DAY(A16)=Budget!$Q$3,Budget!$P$3,0) -> 0 | U16: =N("Audible")-IF(DAY(A16)=Budget!$Q$12,Budget!$P$12,0) -> 0 | V16: =N("Crunchyroll")-IF(DAY(A16)=Budget!$Q$5,Budget!$P$5,0) -> 0 | W16: =N("HBO Max")-IF(DAY(A16)=Budget!$Q$6,Budget!$P$6,0) -> 0 | X16: =N("Netflix")-IF(DAY(A16)=Budget!$Q$7,Budget!$P$7,0) -> 0 | Y16: =N("Spotify")-IF(DAY(A16)=Budget!$Q$8,Budget!$P$8,0) -> 0 | Z16: =N("Truebill")-IF(DAY(A16)=Budget!$Q$9,Budget!$P$9,0) -> 0 | AA16: =SUM(D16:Z16) -> 0
A17: =A16+1 -> 45672 | B17: =B16+AA17 -> 2028.25 | C17: =IF(B17>B16,2,IF(B17=B16, 1,0)) -> 1 | D17: 0 | E17: =N("PAY-LM")+IF(WEEKDAY(A17)=Budget!$C$3,Budget!$B$3,0) -> 0 | F17: =N("Rent")-IF(DAY(A17)=Budget!$G$3,Budget!$F$3,0) -> 0 | G17: =N("Car")-IF(DAY(A17)=Budget!$G$4,Budget!$F$4+Budget!$H$4,0) -> 0 | H17: =N("Mom Rent")-IF(DAY(A17)=Budget!$G$5,Budget!$F$5,0) -> 0 | I17: =N("AT&T")-IF(DAY(A17)=Budget!$G$8,Budget!$F$8,0) -> 0 | J17: =N("GA Power")-IF(DAY(A17)=Budget!$G$9,Budget!$F$9,0) -> 0 | K17: =N("Haircut")-IF(DAY(A17)=Budget!$G$10,Budget!$F$10,0) -> 0 | L17: =N("Groceries")-IF(DAY(A17)=Budget!$G$6,Budget!$F$6,0) -> 0 | M17: =N("Savings")-IF(DAY(A17)=Budget!$G$7,Budget!$F$7,0) -> 0 | N17: =N("Car Insurance")-COUNTIF(Budget!$G$14,A17)*Budget!$F$14 -> 0 | O17: =N("Phone Bill")-COUNTIF(Budget!$G$15, A17)*Budget!$F$15 -> 0 | Q17: =N("Spotify")-IF(AND(DAY($A17)=Budget!$M$3, MONTH($A17)=Budget!$L$3),Budget!$K$3,0) -> 0 | R17: =N("Spotify")-IF(AND(DAY($A17)=Budget!$M$4, MONTH($A17)=Budget!$L$4),Budget!$K$4,0) -> 0 | S17: =N("Spotify")-IF(AND(DAY($A17)=Budget!$M$5, MONTH($A17)=Budget!$L$5),Budget!$K$5,0) -> 0 | T17: =N("Amazon Prime")-IF(DAY(A17)=Budget!$Q$3,Budget!$P$3,0) -> 0 | U17: =N("Audible")-IF(DAY(A17)=Budget!$Q$12,Budget!$P$12,0) -> 0 | V17: =N("Crunchyroll")-IF(DAY(A17)=Budget!$Q$5,Budget!$P$5,0) -> 0 | W17: =N("HBO Max")-IF(DAY(A17)=Budget!$Q$6,Budget!$P$6,0) -> 0 | X17: =N("Netflix")-IF(DAY(A17)=Budget!$Q$7,Budget!$P$7,0) -> 0 | Y17: =N("Spotify")-IF(DAY(A17)=Budget!$Q$8,Budget!$P$8,0) -> 0 | Z17: =N("Truebill")-IF(DAY(A17)=Budget!$Q$9,Budget!$P$9,0) -> 0 | AA17: =SUM(D17:Z17) -> 0
A18: =A17+1 -> 45673 | B18: =B17+AA18 -> 2028.25 | C18: =IF(B18>B17,2,IF(B18=B17, 1,0)) -> 1 | D18: 0 | E18: =N("PAY-LM")+IF(WEEKDAY(A18)=Budget!$C$3,Budget!$B$3,0) -> 0 | F18: =N("Rent")-IF(DAY(A18)=Budget!$G$3,Budget!$F$3,0) -> 0 | G18: =N("Car")-IF(DAY(A18)=Budget!$G$4,Budget!$F$4+Budget!$H$4,0) -> 0 | H18: =N("Mom Rent")-IF(DAY(A18)=Budget!$G$5,Budget!$F$5,0) -> 0 | I18: =N("AT&T")-IF(DAY(A18)=Budget!$G$8,Budget!$F$8,0) -> 0 | J18: =N("GA Power")-IF(DAY(A18)=Budget!$G$9,Budget!$F$9,0) -> 0 | K18: =N("Haircut")-IF(DAY(A18)=Budget!$G$10,Budget!$F$10,0) -> 0 | L18: =N("Groceries")-IF(DAY(A18)=Budget!$G$6,Budget!$F$6,0) -> 0 | M18: =N("Savings")-IF(DAY(A18)=Budget!$G$7,Budget!$F$7,0) -> 0 | N18: =N("Car Insurance")-COUNTIF(Budget!$G$14,A18)*Budget!$F$14 -> 0 | O18: =N("Phone Bill")-COUNTIF(Budget!$G$15, A18)*Budget!$F$15 -> 0 | Q18: =N("Spotify")-IF(AND(DAY($A18)=Budget!$M$3, MONTH($A18)=Budget!$L$3),Budget!$K$3,0) -> 0 | R18: =N("Spotify")-IF(AND(DAY($A18)=Budget!$M$4, MONTH($A18)=Budget!$L$4),Budget!$K$4,0) -> 0 | S18: =N("Spotify")-IF(AND(DAY($A18)=Budget!$M$5, MONTH($A18)=Budget!$L$5),Budget!$K$5,0) -> 0 | T18: =N("Amazon Prime")-IF(DAY(A18)=Budget!$Q$3,Budget!$P$3,0) -> 0 | U18: =N("Audible")-IF(DAY(A18)=Budget!$Q$12,Budget!$P$12,0) -> 0 | V18: =N("Crunchyroll")-IF(DAY(A18)=Budget!$Q$5,Budget!$P$5,0) -> 0 | W18: =N("HBO Max")-IF(DAY(A18)=Budget!$Q$6,Budget!$P$6,0) -> 0 | X18: =N("Netflix")-IF(DAY(A18)=Budget!$Q$7,Budget!$P$7,0) -> 0 | Y18: =N("Spotify")-IF(DAY(A18)=Budget!$Q$8,Budget!$P$8,0) -> 0 | Z18: =N("Truebill")-IF(DAY(A18)=Budget!$Q$9,Budget!$P$9,0) -> 0 | AA18: =SUM(D18:Z18) -> 0
A19: =A18+1 -> 45674 | B19: =B18+AA19 -> 3481.25 | C19: =IF(B19>B18,2,IF(B19=B18, 1,0)) -> 2 | D19: 0 | E19: =N("PAY-LM")+IF(WEEKDAY(A19)=Budget!$C$3,Budget!$B$3,0) -> 1453 | F19: =N("Rent")-IF(DAY(A19)=Budget!$G$3,Budget!$F$3,0) -> 0 | G19: =N("Car")-IF(DAY(A19)=Budget!$G$4,Budget!$F$4+Budget!$H$4,0) -> 0 | H19: =N("Mom Rent")-IF(DAY(A19)=Budget!$G$5,Budget!$F$5,0) -> 0 | I19: =N("AT&T")-IF(DAY(A19)=Budget!$G$8,Budget!$F$8,0) -> 0 | J19: =N("GA Power")-IF(DAY(A19)=Budget!$G$9,Budget!$F$9,0) -> 0 | K19: =N("Haircut")-IF(DAY(A19)=Budget!$G$10,Budget!$F$10,0) -> 0 | L19: =N("Groceries")-IF(DAY(A19)=Budget!$G$6,Budget!$F$6,0) -> 0 | M19: =N("Savings")-IF(DAY(A19)=Budget!$G$7,Budget!$F$7,0) -> 0 | N19: =N("Car Insurance")-COUNTIF(Budget!$G$14,A19)*Budget!$F$14 -> 0 | O19: =N("Phone Bill")-COUNTIF(Budget!$G$15, A19)*Budget!$F$15 -> 0 | Q19: =N("Spotify")-IF(AND(DAY($A19)=Budget!$M$3, MONTH($A19)=Budget!$L$3),Budget!$K$3,0) -> 0 | R19: =N("Spotify")-IF(AND(DAY($A19)=Budget!$M$4, MONTH($A19)=Budget!$L$4),Budget!$K$4,0) -> 0 | S19: =N("Spotify")-IF(AND(DAY($A19)=Budget!$M$5, MONTH($A19)=Budget!$L$5),Budget!$K$5,0) -> 0 | T19: =N("Amazon Prime")-IF(DAY(A19)=Budget!$Q$3,Budget!$P$3,0) -> 0 | U19: =N("Audible")-IF(DAY(A19)=Budget!$Q$12,Budget!$P$12,0) -> 0 | V19: =N("Crunchyroll")-IF(DAY(A19)=Budget!$Q$5,Budget!$P$5,0) -> 0 | W19: =N("HBO Max")-IF(DAY(A19)=Budget!$Q$6,Budget!$P$6,0) -> 0 | X19: =N("Netflix")-IF(DAY(A19)=Budget!$Q$7,Budget!$P$7,0) -> 0 | Y19: =N("Spotify")-IF(DAY(A19)=Budget!$Q$8,Budget!$P$8,0) -> 0 | Z19: =N("Truebill")-IF(DAY(A19)=Budget!$Q$9,Budget!$P$9,0) -> 0 | AA19: =SUM(D19:Z19) -> 1453
A20: =A19+1 -> 45675 | B20: =B19+AA20 -> 3416.25 | C20: =IF(B20>B19,2,IF(B20=B19, 1,0)) -> 0 | D20: 0 | E20: =N("PAY-LM")+IF(WEEKDAY(A20)=Budget!$C$3,Budget!$B$3,0) -> 0 | F20: =N("Rent")-IF(DAY(A20)=Budget!$G$3,Budget!$F$3,0) -> 0 | G20: =N("Car")-IF(DAY(A20)=Budget!$G$4,Budget!$F$4+Budget!$H$4,0) -> 0 | H20: =N("Mom Rent")-IF(DAY(A20)=Budget!$G$5,Budget!$F$5,0) -> 0 | I20: =N("AT&T")-IF(DAY(A20)=Budget!$G$8,Budget!$F$8,0) -> -65 | J20: =N("GA Power")-IF(DAY(A20)=Budget!$G$9,Budget!$F$9,0) -> 0 | K20: =N("Haircut")-IF(DAY(A20)=Budget!$G$10,Budget!$F$10,0) -> 0 | L20: =N("Groceries")-IF(DAY(A20)=Budget!$G$6,Budget!$F$6,0) -> 0 | M20: =N("Savings")-IF(DAY(A20)=Budget!$G$7,Budget!$F$7,0) -> 0 | N20: =N("Car Insurance")-COUNTIF(Budget!$G$14,A20)*Budget!$F$14 -> 0 | O20: =N("Phone Bill")-COUNTIF(Budget!$G$15, A20)*Budget!$F$15 -> 0 | Q20: =N("Spotify")-IF(AND(DAY($A20)=Budget!$M$3, MONTH($A20)=Budget!$L$3),Budget!$K$3,0) -> 0 | R20: =N("Spotify")-IF(AND(DAY($A20)=Budget!$M$4, MONTH($A20)=Budget!$L$4),Budget!$K$4,0) -> 0 | S20: =N("Spotify")-IF(AND(DAY($A20)=Budget!$M$5, MONTH($A20)=Budget!$L$5),Budget!$K$5,0) -> 0 | T20: =N("Amazon Prime")-IF(DAY(A20)=Budget!$Q$3,Budget!$P$3,0) -> 0 | U20: =N("Audible")-IF(DAY(A20)=Budget!$Q$12,Budget!$P$12,0) -> 0 | V20: =N("Crunchyroll")-IF(DAY(A20)=Budget!$Q$5,Budget!$P$5,0) -> 0 | W20: =N("HBO Max")-IF(DAY(A20)=Budget!$Q$6,Budget!$P$6,0) -> 0 | X20: =N("Netflix")-IF(DAY(A20)=Budget!$Q$7,Budget!$P$7,0) -> 0 | Y20: =N("Spotify")-IF(DAY(A20)=Budget!$Q$8,Budget!$P$8,0) -> 0 | Z20: =N("Truebill")-IF(DAY(A20)=Budget!$Q$9,Budget!$P$9,0) -> 0 | AA20: =SUM(D20:Z20) -> -65
A21: =A20+1 -> 45676 | B21: =B20+AA21 -> 3416.25 | C21: =IF(B21>B20,2,IF(B21=B20, 1,0)) -> 1 | D21: 0 | E21: =N("PAY-LM")+IF(WEEKDAY(A21)=Budget!$C$3,Budget!$B$3,0) -> 0 | F21: =N("Rent")-IF(DAY(A21)=Budget!$G$3,Budget!$F$3,0) -> 0 | G21: =N("Car")-IF(DAY(A21)=Budget!$G$4,Budget!$F$4+Budget!$H$4,0) -> 0 | H21: =N("Mom Rent")-IF(DAY(A21)=Budget!$G$5,Budget!$F$5,0) -> 0 | I21: =N("AT&T")-IF(DAY(A21)=Budget!$G$8,Budget!$F$8,0) -> 0 | J21: =N("GA Power")-IF(DAY(A21)=Budget!$G$9,Budget!$F$9,0) -> 0 | K21: =N("Haircut")-IF(DAY(A21)=Budget!$G$10,Budget!$F$10,0) -> 0 | L21: =N("Groceries")-IF(DAY(A21)=Budget!$G$6,Budget!$F$6,0) -> 0 | M21: =N("Savings")-IF(DAY(A21)=Budget!$G$7,Budget!$F$7,0) -> 0 | N21: =N("Car Insurance")-COUNTIF(Budget!$G$14,A21)*Budget!$F$14 -> 0 | O21: =N("Phone Bill")-COUNTIF(Budget!$G$15, A21)*Budget!$F$15 -> 0 | Q21: =N("Spotify")-IF(AND(DAY($A21)=Budget!$M$3, MONTH($A21)=Budget!$L$3),Budget!$K$3,0) -> 0 | R21: =N("Spotify")-IF(AND(DAY($A21)=Budget!$M$4, MONTH($A21)=Budget!$L$4),Budget!$K$4,0) -> 0 | S21: =N("Spotify")-IF(AND(DAY($A21)=Budget!$M$5, MONTH($A21)=Budget!$L$5),Budget!$K$5,0) -> 0 | T21: =N("Amazon Prime")-IF(DAY(A21)=Budget!$Q$3,Budget!$P$3,0) -> 0 | U21: =N("Audible")-IF(DAY(A21)=Budget!$Q$12,Budget!$P$12,0) -> 0 | V21: =N("Crunchyroll")-IF(DAY(A21)=Budget!$Q$5,Budget!$P$5,0) -> 0 | W21: =N("HBO Max")-IF(DAY(A21)=Budget!$Q$6,Budget!$P$6,0) -> 0 | X21: =N("Netflix")-IF(DAY(A21)=Budget!$Q$7,Budget!$P$7,0) -> 0 | Y21: =N("Spotify")-IF(DAY(A21)=Budget!$Q$8,Budget!$P$8,0) -> 0 | Z21: =N("Truebill")-IF(DAY(A21)=Budget!$Q$9,Budget!$P$9,0) -> 0 | AA21: =SUM(D21:Z21) -> 0
A22: =A21+1 -> 45677 | B22: 1937.77 | C22: =IF(B22>B21,2,IF(B22=B21, 1,0)) -> 0 | D22: 0 | E22: =N("PAY-LM")+IF(WEEKDAY(A22)=Budget!$C$3,Budget!$B$3,0) -> 0 | F22: =N("Rent")-IF(DAY(A22)=Budget!$G$3,Budget!$F$3,0) -> 0 | G22: =N("Car")-IF(DAY(A22)=Budget!$G$4,Budget!$F$4+Budget!$H$4,0) -> 0 | H22: =N("Mom Rent")-IF(DAY(A22)=Budget!$G$5,Budget!$F$5,0) -> -850 | I22: =N("AT&T")-IF(DAY(A22)=Budget!$G$8,Budget!$F$8,0) -> 0 | J22: =N("GA Power")-IF(DAY(A22)=Budget!$G$9,Budget!$F$9,0) -> 0 | K22: =N("Haircut")-IF(DAY(A22)=Budget!$G$10,Budget!$F$10,0) -> 0 | L22: =N("Groceries")-IF(DAY(A22)=Budget!$G$6,Budget!$F$6,0) -> 0 | M22: =N("Savings")-IF(DAY(A22)=Budget!$G$7,Budget!$F$7,0) -> 0 | N22: =N("Car Insurance")-COUNTIF(Budget!$G$14,A22)*Budget!$F$14 -> 0 | O22: =N("Phone Bill")-COUNTIF(Budget!$G$15, A22)*Budget!$F$15 -> 0 | Q22: =N("Spotify")-IF(AND(DAY($A22)=Budget!$M$3, MONTH($A22)=Budget!$L$3),Budget!$K$3,0) -> 0 | R22: =N("Spotify")-IF(AND(DAY($A22)=Budget!$M$4, MONTH($A22)=Budget!$L$4),Budget!$K$4,0) -> 0 | S22: =N("Spotify")-IF(AND(DAY($A22)=Budget!$M$5, MONTH($A22)=Budget!$L$5),Budget!$K$5,0) -> 0 | T22: =N("Amazon Prime")-IF(DAY(A22)=Budget!$Q$3,Budget!$P$3,0) -> 0 | U22: =N("Audible")-IF(DAY(A22)=Budget!$Q$12,Budget!$P$12,0) -> 0 | V22: =N("Crunchyroll")-IF(DAY(A22)=Budget!$Q$5,Budget!$P$5,0) -> 0 | W22: =N("HBO Max")-IF(DAY(A22)=Budget!$Q$6,Budget!$P$6,0) -> 0 | X22: =N("Netflix")-IF(DAY(A22)=Budget!$Q$7,Budget!$P$7,0) -> 0 | Y22: =N("Spotify")-IF(DAY(A22)=Budget!$Q$8,Budget!$P$8,0) -> 0 | Z22: =N("Truebill")-IF(DAY(A22)=Budget!$Q$9,Budget!$P$9,0) -> 0 | AA22: =SUM(D22:Z22) -> -850
A23: =A22+1 -> 45678 | B23: =B22+AA23 -> 1937.77 | C23: =IF(B23>B22,2,IF(B23=B22, 1,0)) -> 1 | D23: 0 | E23: =N("PAY-LM")+IF(WEEKDAY(A23)=Budget!$C$3,Budget!$B$3,0) -> 0 | F23: =N("Rent")-IF(DAY(A23)=Budget!$G$3,Budget!$F$3,0) -> 0 | G23: =N("Car")-IF(DAY(A23)=Budget!$G$4,Budget!$F$4+Budget!$H$4,0) -> 0 | H23: =N("Mom Rent")-IF(DAY(A23)=Budget!$G$5,Budget!$F$5,0) -> 0 | I23: =N("AT&T")-IF(DAY(A23)=Budget!$G$8,Budget!$F$8,0) -> 0 | J23: =N("GA Power")-IF(DAY(A23)=Budget!$G$9,Budget!$F$9,0) -> 0 | K23: =N("Haircut")-IF(DAY(A23)=Budget!$G$10,Budget!$F$10,0) -> 0 | L23: =N("Groceries")-IF(DAY(A23)=Budget!$G$6,Budget!$F$6,0) -> 0 | M23: =N("Savings")-IF(DAY(A23)=Budget!$G$7,Budget!$F$7,0) -> 0 | N23: =N("Car Insurance")-COUNTIF(Budget!$G$14,A23)*Budget!$F$14 -> 0 | O23: =N("Phone Bill")-COUNTIF(Budget!$G$15, A23)*Budget!$F$15 -> 0 | Q23: =N("Spotify")-IF(AND(DAY($A23)=Budget!$M$3, MONTH($A23)=Budget!$L$3),Budget!$K$3,0) -> 0 | R23: =N("Spotify")-IF(AND(DAY($A23)=Budget!$M$4, MONTH($A23)=Budget!$L$4),Budget!$K$4,0) -> 0 | S23: =N("Spotify")-IF(AND(DAY($A23)=Budget!$M$5, MONTH($A23)=Budget!$L$5),Budget!$K$5,0) -> 0 | T23: =N("Amazon Prime")-IF(DAY(A23)=Budget!$Q$3,Budget!$P$3,0) -> 0 | U23: =N("Audible")-IF(DAY(A23)=Budget!$Q$12,Budget!$P$12,0) -> 0 | V23: =N("Crunchyroll")-IF(DAY(A23)=Budget!$Q$5,Budget!$P$5,0) -> 0 | W23: =N("HBO Max")-IF(DAY(A23)=Budget!$Q$6,Budget!$P$6,0) -> 0 | X23: =N("Netflix")-IF(DAY(A23)=Budget!$Q$7,Budget!$P$7,0) -> 0 | Y23: =N("Spotify")-IF(DAY(A23)=Budget!$Q$8,Budget!$P$8,0) -> 0 | Z23: =N("Truebill")-IF(DAY(A23)=Budget!$Q$9,Budget!$P$9,0) -> 0 | AA23: =SUM(D23:Z23) -> 0
A24: =A23+1 -> 45679 | B24: =B23+AA24 -> 1937.77 | C24: =IF(B24>B23,2,IF(B24=B23, 1,0)) -> 1 | D24: 0 | E24: =N("PAY-LM")+IF(WEEKDAY(A24)=Budget!$C$3,Budget!$B$3,0) -> 0 | F24: =N("Rent")-IF(DAY(A24)=Budget!$G$3,Budget!$F$3,0) -> 0 | G24: =N("Car")-IF(DAY(A24)=Budget!$G$4,Budget!$F$4+Budget!$H$4,0) -> 0 | H24: =N("Mom Rent")-IF(DAY(A24)=Budget!$G$5,Budget!$F$5,0) -> 0 | I24: =N("AT&T")-IF(DAY(A24)=Budget!$G$8,Budget!$F$8,0) -> 0 | J24: =N("GA Power")-IF(DAY(A24)=Budget!$G$9,Budget!$F$9,0) -> 0 | K24: =N("Haircut")-IF(DAY(A24)=Budget!$G$10,Budget!$F$10,0) -> 0 | L24: =N("Groceries")-IF(DAY(A24)=Budget!$G$6,Budget!$F$6,0) -> 0 | M24: =N("Savings")-IF(DAY(A24)=Budget!$G$7,Budget!$F$7,0) -> 0 | N24: =N("Car Insurance")-COUNTIF(Budget!$G$14,A24)*Budget!$F$14 -> 0 | O24: =N("Phone Bill")-COUNTIF(Budget!$G$15, A24)*Budget!$F$15 -> 0 | Q24: =N("Spotify")-IF(AND(DAY($A24)=Budget!$M$3, MONTH($A24)=Budget!$L$3),Budget!$K$3,0) -> 0 | R24: =N("Spotify")-IF(AND(DAY($A24)=Budget!$M$4, MONTH($A24)=Budget!$L$4),Budget!$K$4,0) -> 0 | S24: =N("Spotify")-IF(AND(DAY($A24)=Budget!$M$5, MONTH($A24)=Budget!$L$5),Budget!$K$5,0) -> 0 | T24: =N("Amazon Prime")-IF(DAY(A24)=Budget!$Q$3,Budget!$P$3,0) -> 0 | U24: =N("Audible")-IF(DAY(A24)=Budget!$Q$12,Budget!$P$12,0) -> 0 | V24: =N("Crunchyroll")-IF(DAY(A24)=Budget!$Q$5,Budget!$P$5,0) -> 0 | W24: =N("HBO Max")-IF(DAY(A24)=Budget!$Q$6,Budget!$P$6,0) -> 0 | X24: =N("Netflix")-IF(DAY(A24)=Budget!$Q$7,Budget!$P$7,0) -> 0 | Y24: =N("Spotify")-IF(DAY(A24)=Budget!$Q$8,Budget!$P$8,0) -> 0 | Z24: =N("Truebill")-IF(DAY(A24)=Budget!$Q$9,Budget!$P$9,0) -> 0 | AA24: =SUM(D24:Z24) -> 0
A25: =A24+1 -> 45680 | B25: =B24+AA25 -> 1937.77 | C25: =IF(B25>B24,2,IF(B25=B24, 1,0)) -> 1 | D25: 0 | E25: =N("PAY-LM")+IF(WEEKDAY(A25)=Budget!$C$3,Budget!$B$3,0) -> 0 | F25: =N("Rent")-IF(DAY(A25)=Budget!$G$3,Budget!$F$3,0) -> 0 | G25: =N("Car")-IF(DAY(A25)=Budget!$G$4,Budget!$F$4+Budget!$H$4,0) -> 0 | H25: =N("Mom Rent")-IF(DAY(A25)=Budget!$G$5,Budget!$F$5,0) -> 0 | I25: =N("AT&T")-IF(DAY(A25)=Budget!$G$8,Budget!$F$8,0) -> 0 | J25: =N("GA Power")-IF(DAY(A25)=Budget!$G$9,Budget!$F$9,0) -> 0 | K25: =N("Haircut")-IF(DAY(A25)=Budget!$G$10,Budget!$F$10,0) -> 0 | L25: =N("Groceries")-IF(DAY(A25)=Budget!$G$6,Budget!$F$6,0) -> 0 | M25: =N("Savings")-IF(DAY(A25)=Budget!$G$7,Budget!$F$7,0) -> 0 | N25: =N("Car Insurance")-COUNTIF(Budget!$G$14,A25)*Budget!$F$14 -> 0 | O25: =N("Phone Bill")-COUNTIF(Budget!$G$15, A25)*Budget!$F$15 -> 0 | Q25: =N("Spotify")-IF(AND(DAY($A25)=Budget!$M$3, MONTH($A25)=Budget!$L$3),Budget!$K$3,0) -> 0 | R25: =N("Spotify")-IF(AND(DAY($A25)=Budget!$M$4, MONTH($A25)=Budget!$L$4),Budget!$K$4,0) -> 0 | S25: =N("Spotify")-IF(AND(DAY($A25)=Budget!$M$5, MONTH($A25)=Budget!$L$5),Budget!$K$5,0) -> 0 | T25: =N("Amazon Prime")-IF(DAY(A25)=Budget!$Q$3,Budget!$P$3,0) -> 0 | U25: =N("Audible")-IF(DAY(A25)=Budget!$Q$12,Budget!$P$12,0) -> 0 | V25: =N("Crunchyroll")-IF(DAY(A25)=Budget!$Q$5,Budget!$P$5,0) -> 0 | W25: =N("HBO Max")-IF(DAY(A25)=Budget!$Q$6,Budget!$P$6,0) -> 0 | X25: =N("Netflix")-IF(DAY(A25)=Budget!$Q$7,Budget!$P$7,0) -> 0 | Y25: =N("Spotify")-IF(DAY(A25)=Budget!$Q$8,Budget!$P$8,0) -> 0 | Z25: =N("Truebill")-IF(DAY(A25)=Budget!$Q$9,Budget!$P$9,0) -> 0 | AA25: =SUM(D25:Z25) -> 0
A26: =A25+1 -> 45681 | B26: =B25+AA26 -> 3390.77 | C26: =IF(B26>B25,2,IF(B26=B25, 1,0)) -> 2 | D26: 0 | E26: =N("PAY-LM")+IF(WEEKDAY(A26)=Budget!$C$3,Budget!$B$3,0) -> 1453 | F26: =N("Rent")-IF(DAY(A26)=Budget!$G$3,Budget!$F$3,0) -> 0 | G26: =N("Car")-IF(DAY(A26)=Budget!$G$4,Budget!$F$4+Budget!$H$4,0) -> 0 | H26: =N("Mom Rent")-IF(DAY(A26)=Budget!$G$5,Budget!$F$5,0) -> 0 | I26: =N("AT&T")-IF(DAY(A26)=Budget!$G$8,Budget!$F$8,0) -> 0 | J26: =N("GA Power")-IF(DAY(A26)=Budget!$G$9,Budget!$F$9,0) -> 0 | K26: =N("Haircut")-IF(DAY(A26)=Budget!$G$10,Budget!$F$10,0) -> 0 | L26: =N("Groceries")-IF(DAY(A26)=Budget!$G$6,Budget!$F$6,0) -> 0 | M26: =N("Savings")-IF(DAY(A26)=Budget!$G$7,Budget!$F$7,0) -> 0 | N26: =N("Car Insurance")-COUNTIF(Budget!$G$14,A26)*Budget!$F$14 -> 0 | O26: =N("Phone Bill")-COUNTIF(Budget!$G$15, A26)*Budget!$F$15 -> 0 | Q26: =N("Spotify")-IF(AND(DAY($A26)=Budget!$M$3, MONTH($A26)=Budget!$L$3),Budget!$K$3,0) -> 0 | R26: =N("Spotify")-IF(AND(DAY($A26)=Budget!$M$4, MONTH($A26)=Budget!$L$4),Budget!$K$4,0) -> 0 | S26: =N("Spotify")-IF(AND(DAY($A26)=Budget!$M$5, MONTH($A26)=Budget!$L$5),Budget!$K$5,0) -> 0 | T26: =N("Amazon Prime")-IF(DAY(A26)=Budget!$Q$3,Budget!$P$3,0) -> 0 | U26: =N("Audible")-IF(DAY(A26)=Budget!$Q$12,Budget!$P$12,0) -> 0 | V26: =N("Crunchyroll")-IF(DAY(A26)=Budget!$Q$5,Budget!$P$5,0) -> 0 | W26: =N("HBO Max")-IF(DAY(A26)=Budget!$Q$6,Budget!$P$6,0) -> 0 | X26: =N("Netflix")-IF(DAY(A26)=Budget!$Q$7,Budget!$P$7,0) -> 0 | Y26: =N("Spotify")-IF(DAY(A26)=Budget!$Q$8,Budget!$P$8,0) -> 0 | Z26: =N("Truebill")-IF(DAY(A26)=Budget!$Q$9,Budget!$P$9,0) -> 0 | AA26: =SUM(D26:Z26) -> 1453
A27: =A26+1 -> 45682 | B27: =B26+AA27 -> 3390.77 | C27: =IF(B27>B26,2,IF(B27=B26, 1,0)) -> 1 | D27: 0 | E27: =N("PAY-LM")+IF(WEEKDAY(A27)=Budget!$C$3,Budget!$B$3,0) -> 0 | F27: =N("Rent")-IF(DAY(A27)=Budget!$G$3,Budget!$F$3,0) -> 0 | G27: =N("Car")-IF(DAY(A27)=Budget!$G$4,Budget!$F$4+Budget!$H$4,0) -> 0 | H27: =N("Mom Rent")-IF(DAY(A27)=Budget!$G$5,Budget!$F$5,0) -> 0 | I27: =N("AT&T")-IF(DAY(A27)=Budget!$G$8,Budget!$F$8,0) -> 0 | J27: =N("GA Power")-IF(DAY(A27)=Budget!$G$9,Budget!$F$9,0) -> 0 | K27: =N("Haircut")-IF(DAY(A27)=Budget!$G$10,Budget!$F$10,0) -> 0 | L27: =N("Groceries")-IF(DAY(A27)=Budget!$G$6,Budget!$F$6,0) -> 0 | M27: =N("Savings")-IF(DAY(A27)=Budget!$G$7,Budget!$F$7,0) -> 0 | N27: =N("Car Insurance")-COUNTIF(Budget!$G$14,A27)*Budget!$F$14 -> 0 | O27: =N("Phone Bill")-COUNTIF(Budget!$G$15, A27)*Budget!$F$15 -> 0 | Q27: =N("Spotify")-IF(AND(DAY($A27)=Budget!$M$3, MONTH($A27)=Budget!$L$3),Budget!$K$3,0) -> 0 | R27: =N("Spotify")-IF(AND(DAY($A27)=Budget!$M$4, MONTH($A27)=Budget!$L$4),Budget!$K$4,0) -> 0 | S27: =N("Spotify")-IF(AND(DAY($A27)=Budget!$M$5, MONTH($A27)=Budget!$L$5),Budget!$K$5,0) -> 0 | T27: =N("Amazon Prime")-IF(DAY(A27)=Budget!$Q$3,Budget!$P$3,0) -> 0 | U27: =N("Audible")-IF(DAY(A27)=Budget!$Q$12,Budget!$P$12,0) -> 0 | V27: =N("Crunchyroll")-IF(DAY(A27)=Budget!$Q$5,Budget!$P$5,0) -> 0 | W27: =N("HBO Max")-IF(DAY(A27)=Budget!$Q$6,Budget!$P$6,0) -> 0 | X27: =N("Netflix")-IF(DAY(A27)=Budget!$Q$7,Budget!$P$7,0) -> 0 | Y27: =N("Spotify")-IF(DAY(A27)=Budget!$Q$8,Budget!$P$8,0) -> 0 | Z27: =N("Truebill")-IF(DAY(A27)=Budget!$Q$9,Budget!$P$9,0) -> 0 | AA27: =SUM(D27:Z27) -> 0
A28: =A27+1 -> 45683 | B28: =B27+AA28 -> 2990.77 | C28: =IF(B28>B27,2,IF(B28=B27, 1,0)) -> 0 | D28: 0 | E28: =N("PAY-LM")+IF(WEEKDAY(A28)=Budget!$C$3,Budget!$B$3,0) -> 0 | F28: =N("Rent")-IF(DAY(A28)=Budget!$G$3,Budget!$F$3,0) -> 0 | G28: =N("Car")-IF(DAY(A28)=Budget!$G$4,Budget!$F$4+Budget!$H$4,0) -> 0 | H28: =N("Mom Rent")-IF(DAY(A28)=Budget!$G$5,Budget!$F$5,0) -> 0 | I28: =N("AT&T")-IF(DAY(A28)=Budget!$G$8,Budget!$F$8,0) -> 0 | J28: =N("GA Power")-IF(DAY(A28)=Budget!$G$9,Budget!$F$9,0) -> 0 | K28: =N("Haircut")-IF(DAY(A28)=Budget!$G$10,Budget!$F$10,0) -> -400 | L28: =N("Groceries")-IF(DAY(A28)=Budget!$G$6,Budget!$F$6,0) -> 0 | M28: =N("Savings")-IF(DAY(A28)=Budget!$G$7,Budget!$F$7,0) -> 0 | N28: =N("Car Insurance")-COUNTIF(Budget!$G$14,A28)*Budget!$F$14 -> 0 | O28: =N("Phone Bill")-COUNTIF(Budget!$G$15, A28)*Budget!$F$15 -> 0 | Q28: =N("Spotify")-IF(AND(DAY($A28)=Budget!$M$3, MONTH($A28)=Budget!$L$3),Budget!$K$3,0) -> 0 | R28: =N("Spotify")-IF(AND(DAY($A28)=Budget!$M$4, MONTH($A28)=Budget!$L$4),Budget!$K$4,0) -> 0 | S28: =N("Spotify")-IF(AND(DAY($A28)=Budget!$M$5, MONTH($A28)=Budget!$L$5),Budget!$K$5,0) -> 0 | T28: =N("Amazon Prime")-IF(DAY(A28)=Budget!$Q$3,Budget!$P$3,0) -> 0 | U28: =N("Audible")-IF(DAY(A28)=Budget!$Q$12,Budget!$P$12,0) -> 0 | V28: =N("Crunchyroll")-IF(DAY(A28)=Budget!$Q$5,Budget!$P$5,0) -> 0 | W28: =N("HBO Max")-IF(DAY(A28)=Budget!$Q$6,Budget!$P$6,0) -> 0 | X28: =N("Netflix")-IF(DAY(A28)=Budget!$Q$7,Budget!$P$7,0) -> 0 | Y28: =N("Spotify")-IF(DAY(A28)=Budget!$Q$8,Budget!$P$8,0) -> 0 | Z28: =N("Truebill")-IF(DAY(A28)=Budget!$Q$9,Budget!$P$9,0) -> 0 | AA28: =SUM(D28:Z28) -> -400
A29: =A28+1 -> 45684 | B29: =B28+AA29 -> 2990.77 | C29: =IF(B29>B28,2,IF(B29=B28, 1,0)) -> 1 | D29: 0 | E29: =N("PAY-LM")+IF(WEEKDAY(A29)=Budget!$C$3,Budget!$B$3,0) -> 0 | F29: =N("Rent")-IF(DAY(A29)=Budget!$G$3,Budget!$F$3,0) -> 0 | G29: =N("Car")-IF(DAY(A29)=Budget!$G$4,Budget!$F$4+Budget!$H$4,0) -> 0 | H29: =N("Mom Rent")-IF(DAY(A29)=Budget!$G$5,Budget!$F$5,0) -> 0 | I29: =N("AT&T")-IF(DAY(A29)=Budget!$G$8,Budget!$F$8,0) -> 0 | J29: =N("GA Power")-IF(DAY(A29)=Budget!$G$9,Budget!$F$9,0) -> 0 | K29: =N("Haircut")-IF(DAY(A29)=Budget!$G$10,Budget!$F$10,0) -> 0 | L29: =N("Groceries")-IF(DAY(A29)=Budget!$G$6,Budget!$F$6,0) -> 0 | M29: =N("Savings")-IF(DAY(A29)=Budget!$G$7,Budget!$F$7,0) -> 0 | N29: =N("Car Insurance")-COUNTIF(Budget!$G$14,A29)*Budget!$F$14 -> 0 | O29: =N("Phone Bill")-COUNTIF(Budget!$G$15, A29)*Budget!$F$15 -> 0 | Q29: =N("Spotify")-IF(AND(DAY($A29)=Budget!$M$3, MONTH($A29)=Budget!$L$3),Budget!$K$3,0) -> 0 | R29: =N("Spotify")-IF(AND(DAY($A29)=Budget!$M$4, MONTH($A29)=Budget!$L$4),Budget!$K$4,0) -> 0 | S29: =N("Spotify")-IF(AND(DAY($A29)=Budget!$M$5, MONTH($A29)=Budget!$L$5),Budget!$K$5,0) -> 0 | T29: =N("Amazon Prime")-IF(DAY(A29)=Budget!$Q$3,Budget!$P$3,0) -> 0 | U29: =N("Audible")-IF(DAY(A29)=Budget!$Q$12,Budget!$P$12,0) -> 0 | V29: =N("Crunchyroll")-IF(DAY(A29)=Budget!$Q$5,Budget!$P$5,0) -> 0 | W29: =N("HBO Max")-IF(DAY(A29)=Budget!$Q$6,Budget!$P$6,0) -> 0 | X29: =N("Netflix")-IF(DAY(A29)=Budget!$Q$7,Budget!$P$7,0) -> 0 | Y29: =N("Spotify")-IF(DAY(A29)=Budget!$Q$8,Budget!$P$8,0) -> 0 | Z29: =N("Truebill")-IF(DAY(A29)=Budget!$Q$9,Budget!$P$9,0) -> 0 | AA29: =SUM(D29:Z29) -> 0
A30: =A29+1 -> 45685 | B30: 1216 | C30: =IF(B30>B29,2,IF(B30=B29, 1,0)) -> 0 | D30: 0 | E30: =N("PAY-LM")+IF(WEEKDAY(A30)=Budget!$C$3,Budget!$B$3,0) -> 0 | F30: =N("Rent")-IF(DAY(A30)=Budget!$G$3,Budget!$F$3,0) -> 0 | G30: =N("Car")-IF(DAY(A30)=Budget!$G$4,Budget!$F$4+Budget!$H$4,0) -> 0 | H30: =N("Mom Rent")-IF(DAY(A30)=Budget!$G$5,Budget!$F$5,0) -> 0 | I30: =N("AT&T")-IF(DAY(A30)=Budget!$G$8,Budget!$F$8,0) -> 0 | J30: =N("GA Power")-IF(DAY(A30)=Budget!$G$9,Budget!$F$9,0) -> 0 | K30: =N("Haircut")-IF(DAY(A30)=Budget!$G$10,Budget!$F$10,0) -> 0 | L30: =N("Groceries")-IF(DAY(A30)=Budget!$G$6,Budget!$F$6,0) -> 0 | M30: =N("Savings")-IF(DAY(A30)=Budget!$G$7,Budget!$F$7,0) -> -1000 | N30: =N("Car Insurance")-COUNTIF(Budget!$G$14,A30)*Budget!$F$14 -> 0 | O30: =N("Phone Bill")-COUNTIF(Budget!$G$15, A30)*Budget!$F$15 -> 0 | Q30: =N("Spotify")-IF(AND(DAY($A30)=Budget!$M$3, MONTH($A30)=Budget!$L$3),Budget!$K$3,0) -> 0 | R30: =N("Spotify")-IF(AND(DAY($A30)=Budget!$M$4, MONTH($A30)=Budget!$L$4),Budget!$K$4,0) -> 0 | S30: =N("Spotify")-IF(AND(DAY($A30)=Budget!$M$5, MONTH($A30)=Budget!$L$5),Budget!$K$5,0) -> 0 | T30: =N("Amazon Prime")-IF(DAY(A30)=Budget!$Q$3,Budget!$P$3,0) -> 0 | U30: =N("Audible")-IF(DAY(A30)=Budget!$Q$12,Budget!$P$12,0) -> 0 | V30: =N("Crunchyroll")-IF(DAY(A30)=Budget!$Q$5,Budget!$P$5,0) -> 0 | W30: =N("HBO Max")-IF(DAY(A30)=Budget!$Q$6,Budget!$P$6,0) -> 0 | X30: =N("Netflix")-IF(DAY(A30)=Budget!$Q$7,Budget!$P$7,0) -> 0 | Y30: =N("Spotify")-IF(DAY(A30)=Budget!$Q$8,Budget!$P$8,0) -> -150 | Z30: =N("Truebill")-IF(DAY(A30)=Budget!$Q$9,Budget!$P$9,0) -> 0 | AA30: =SUM(D30:Z30) -> -1150
A31: =A30+1 -> 45686 | B31: =B30+AA31 -> 1191.4 | C31: =IF(B31>B30,2,IF(B31=B30, 1,0)) -> 0 | D31: 0 | E31: =N("PAY-LM")+IF(WEEKDAY(A31)=Budget!$C$3,Budget!$B$3,0) -> 0 | F31: =N("Rent")-IF(DAY(A31)=Budget!$G$3,Budget!$F$3,0) -> 0 | G31: =N("Car")-IF(DAY(A31)=Budget!$G$4,Budget!$F$4+Budget!$H$4,0) -> 0 | H31: =N("Mom Rent")-IF(DAY(A31)=Budget!$G$5,Budget!$F$5,0) -> 0 | I31: =N("AT&T")-IF(DAY(A31)=Budget!$G$8,Budget!$F$8,0) -> 0 | J31: =N("GA Power")-IF(DAY(A31)=Budget!$G$9,Budget!$F$9,0) -> 0 | K31: =N("Haircut")-IF(DAY(A31)=Budget!$G$10,Budget!$F$10,0) -> 0 | L31: =N("Groceries")-IF(DAY(A31)=Budget!$G$6,Budget!$F$6,0) -> 0 | M31: =N("Savings")-IF(DAY(A31)=Budget!$G$7,Budget!$F$7,0) -> 0 | N31: =N("Car Insurance")-COUNTIF(Budget!$G$14,A31)*Budget!$F$14 -> 0 | O31: =N("Phone Bill")-COUNTIF(Budget!$G$15, A31)*Budget!$F$15 -> 0 | Q31: =N("Spotify")-IF(AND(DAY($A31)=Budget!$M$3, MONTH($A31)=Budget!$L$3),Budget!$K$3,0) -> 0 | R31: =N("Spotify")-IF(AND(DAY($A31)=Budget!$M$4, MONTH($A31)=Budget!$L$4),Budget!$K$4,0) -> 0 | S31: =N("Spotify")-IF(AND(DAY($A31)=Budget!$M$5, MONTH($A31)=Budget!$L$5),Budget!$K$5,0) -> 0 | T31: =N("Amazon Prime")-IF(DAY(A31)=Budget!$Q$3,Budget!$P$3,0) -> 0 | U31: =N("Audible")-IF(DAY(A31)=Budget!$Q$12,Budget!$P$12,0) -> 0 | V31: =N("Crunchyroll")-IF(DAY(A31)=Budget!$Q$5,Budget!$P$5,0) -> -24.6 | W31: =N("HBO Max")-IF(DAY(A31)=Budget!$Q$6,Budget!$P$6,0) -> 0 | X31: =N("Netflix")-IF(DAY(A31)=Budget!$Q$7,Budget!$P$7,0) -> 0 | Y31: =N("Spotify")-IF(DAY(A31)=Budget!$Q$8,Budget!$P$8,0) -> 0 | Z31: =N("Truebill")-IF(DAY(A31)=Budget!$Q$9,Budget!$P$9,0) -> 0 | AA31: =SUM(D31:Z31) -> -24.6
A32: =A31+1 -> 45687 | B32: =B31+AA32 -> 1191.4 | C32: =IF(B32>B31,2,IF(B32=B31, 1,0)) -> 1 | D32: 0 | E32: =N("PAY-LM")+IF(WEEKDAY(A32)=Budget!$C$3,Budget!$B$3,0) -> 0 | F32: =N("Rent")-IF(DAY(A32)=Budget!$G$3,Budget!$F$3,0) -> 0 | G32: =N("Car")-IF(DAY(A32)=Budget!$G$4,Budget!$F$4+Budget!$H$4,0) -> 0 | H32: =N("Mom Rent")-IF(DAY(A32)=Budget!$G$5,Budget!$F$5,0) -> 0 | I32: =N("AT&T")-IF(DAY(A32)=Budget!$G$8,Budget!$F$8,0) -> 0 | J32: =N("GA Power")-IF(DAY(A32)=Budget!$G$9,Budget!$F$9,0) -> 0 | K32: =N("Haircut")-IF(DAY(A32)=Budget!$G$10,Budget!$F$10,0) -> 0 | L32: =N("Groceries")-IF(DAY(A32)=Budget!$G$6,Budget!$F$6,0) -> 0 | M32: =N("Savings")-IF(DAY(A32)=Budget!$G$7,Budget!$F$7,0) -> 0 | N32: =N("Car Insurance")-COUNTIF(Budget!$G$14,A32)*Budget!$F$14 -> 0 | O32: =N("Phone Bill")-COUNTIF(Budget!$G$15, A32)*Budget!$F$15 -> 0 | Q32: =N("Spotify")-IF(AND(DAY($A32)=Budget!$M$3, MONTH($A32)=Budget!$L$3),Budget!$K$3,0) -> 0 | R32: =N("Spotify")-IF(AND(DAY($A32)=Budget!$M$4, MONTH($A32)=Budget!$L$4),Budget!$K$4,0) -> 0 | S32: =N("Spotify")-IF(AND(DAY($A32)=Budget!$M$5, MONTH($A32)=Budget!$L$5),Budget!$K$5,0) -> 0 | T32: =N("Amazon Prime")-IF(DAY(A32)=Budget!$Q$3,Budget!$P$3,0) -> 0 | U32: =N("Audible")-IF(DAY(A32)=Budget!$Q$12,Budget!$P$12,0) -> 0 | V32: =N("Crunchyroll")-IF(DAY(A32)=Budget!$Q$5,Budget!$P$5,0) -> 0 | W32: =N("HBO Max")-IF(DAY(A32)=Budget!$Q$6,Budget!$P$6,0) -> 0 | X32: =N("Netflix")-IF(DAY(A32)=Budget!$Q$7,Budget!$P$7,0) -> 0 | Y32: =N("Spotify")-IF(DAY(A32)=Budget!$Q$8,Budget!$P$8,0) -> 0 | Z32: =N("Truebill")-IF(DAY(A32)=Budget!$Q$9,Budget!$P$9,0) -> 0 | AA32: =SUM(D32:Z32) -> 0
A33: =A32+1 -> 45688 | B33: =B32+AA33 -> 2644.4 | C33: =IF(B33>B32,2,IF(B33=B32, 1,0)) -> 2 | D33: 0 | E33: =N("PAY-LM")+IF(WEEKDAY(A33)=Budget!$C$3,Budget!$B$3,0) -> 1453 | F33: =N("Rent")-IF(DAY(A33)=Budget!$G$3,Budget!$F$3,0) -> 0 | G33: =N("Car")-IF(DAY(A33)=Budget!$G$4,Budget!$F$4+Budget!$H$4,0) -> 0 | H33: =N("Mom Rent")-IF(DAY(A33)=Budget!$G$5,Budget!$F$5,0) -> 0 | I33: =N("AT&T")-IF(DAY(A33)=Budget!$G$8,Budget!$F$8,0) -> 0 | J33: =N("GA Power")-IF(DAY(A33)=Budget!$G$9,Budget!$F$9,0) -> 0 | K33: =N("Haircut")-IF(DAY(A33)=Budget!$G$10,Budget!$F$10,0) -> 0 | L33: =N("Groceries")-IF(DAY(A33)=Budget!$G$6,Budget!$F$6,0) -> 0 | M33: =N("Savings")-IF(DAY(A33)=Budget!$G$7,Budget!$F$7,0) -> 0 | N33: =N("Car Insurance")-COUNTIF(Budget!$G$14,A33)*Budget!$F$14 -> 0 | O33: =N("Phone Bill")-COUNTIF(Budget!$G$15, A33)*Budget!$F$15 -> 0 | Q33: =N("Spotify")-IF(AND(DAY($A33)=Budget!$M$3, MONTH($A33)=Budget!$L$3),Budget!$K$3,0) -> 0 | R33: =N("Spotify")-IF(AND(DAY($A33)=Budget!$M$4, MONTH($A33)=Budget!$L$4),Budget!$K$4,0) -> 0 | S33: =N("Spotify")-IF(AND(DAY($A33)=Budget!$M$5, MONTH($A33)=Budget!$L$5),Budget!$K$5,0) -> 0 | T33: =N("Amazon Prime")-IF(DAY(A33)=Budget!$Q$3,Budget!$P$3,0) -> 0 | U33: =N("Audible")-IF(DAY(A33)=Budget!$Q$12,Budget!$P$12,0) -> 0 | V33: =N("Crunchyroll")-IF(DAY(A33)=Budget!$Q$5,Budget!$P$5,0) -> 0 | W33: =N("HBO Max")-IF(DAY(A33)=Budget!$Q$6,Budget!$P$6,0) -> 0 | X33: =N("Netflix")-IF(DAY(A33)=Budget!$Q$7,Budget!$P$7,0) -> 0 | Y33: =N("Spotify")-IF(DAY(A33)=Budget!$Q$8,Budget!$P$8,0) -> 0 | Z33: =N("Truebill")-IF(DAY(A33)=Budget!$Q$9,Budget!$P$9,0) -> 0 | AA33: =SUM(D33:Z33) -> 1453
D35: Miscellaneous | E35: Monthly Expenses | N35: =Budget!$E$12 -> Annual Expenses | Q35: Credit Card | T35: Subscriptions | AA35: TOTAL | AC35: =SUMIF(D37:Z64,"<0") -> -5257.82 | AD35: =SUM(E37:E64) -> 5812
A36: =EDATE(A2,1) -> 45689 | E36: =Budget!$A$3 -> PAY-LM | F36: =Budget!$E$3 -> Rent | G36: =Budget!$E$4 -> Car | H36: =Budget!$E$5 -> Mom Rent | I36: =Budget!$E$8 -> AT&T | J36: =Budget!$E$9 -> GA Power | K36: =Budget!$E$10 -> TH | L36: =Budget!$E$6 -> Groceries | M36: =Budget!$E$7 -> Savings | N36: =Budget!$E$14 -> Car Insurance | O36: =Budget!$E$15 -> Phone Bill | Q36: =Budget!$J$3 -> Capital One | R36: =Budget!$J$4 -> Chase | S36: =Budget!$J$5 -> NFCU | T36: =Budget!$O$3 -> Amazon Prime | U36: =Budget!$O$12 -> Audible | V36: =Budget!$O$5 -> Netflix | W36: =Budget!$O$6 -> Spotify | X36: =Budget!$O$7 -> Rocket Money | Y36: =Budget!$O$8 -> Little4Much | Z36: =Budget!$O$9 -> None | AC36: =AD35+AC35 -> 554.18
A37: =A36 -> 45689 | B37: =B33+AA37 -> 911.4 | C37: =IF(B37>B32,2,IF(B37=B32, 1,0)) -> 0 | D37: 0 | E37: =N("PAY-LM")+IF(WEEKDAY(A37)=Budget!$C$3,Budget!$B$3,0) -> 0 | F37: =N("Rent")-IF(DAY(A37)=Budget!$G$3,Budget!$F$3,0) -> -1733 | G37: =N("Car")-IF(DAY(A37)=Budget!$G$4,Budget!$F$4+Budget!$H$4,0) -> 0 | H37: =N("Mom Rent")-IF(DAY(A37)=Budget!$G$5,Budget!$F$5,0) -> 0 | I37: =N("AT&T")-IF(DAY(A37)=Budget!$G$8,Budget!$F$8,0) -> 0 | J37: =N("GA Power")-IF(DAY(A37)=Budget!$G$9,Budget!$F$9,0) -> 0 | K37: =N("Haircut")-IF(DAY(A37)=Budget!$G$10,Budget!$F$10,0) -> 0 | L37: =N("Groceries")-IF(DAY(A37)=Budget!$G$6,Budget!$F$6,0) -> 0 | M37: =N("Savings")-IF(DAY(A37)=Budget!$G$7,Budget!$F$7,0) -> 0 | N37: =N("Car Insurance")-COUNTIF(Budget!$G$14, A37)*Budget!$F$14 -> 0 | O37: =N("Phone Bill")-COUNTIF(Budget!$G$15, A37)*Budget!$F$15 -> 0 | Q37: =N("Spotify")-IF(AND(DAY($A37)=Budget!$M$3, MONTH($A37)=Budget!$L$3),Budget!$K$3,0) -> 0 | R37: =N("Spotify")-IF(AND(DAY($A37)=Budget!$M$4, MONTH($A37)=Budget!$L$4),Budget!$K$4,0) -> 0 | S37: =N("Spotify")-IF(AND(DAY($A37)=Budget!$M$5, MONTH($A37)=Budget!$L$5),Budget!$K$5,0) -> 0 | T37: =N("Amazon Prime")-IF(DAY(A37)=Budget!$Q$3,Budget!$P$3,0) -> 0 | U37: =N("Audible")-IF(DAY(A37)=Budget!$Q$12,Budget!$P$12,0) -> 0 | V37: =N("Crunchyroll")-IF(DAY(A37)=Budget!$Q$5,Budget!$P$5,0) -> 0 | W37: =N("HBO Max")-IF(DAY(A37)=Budget!$Q$6,Budget!$P$6,0) -> 0 | X37: =N("Netflix")-IF(DAY(A37)=Budget!$Q$7,Budget!$P$7,0) -> 0 | Y37: =N("Spotify")-IF(DAY(A37)=Budget!$Q$8,Budget!$P$8,0) -> 0 | Z37: =N("Truebill")-IF(DAY(A37)=Budget!$Q$9,Budget!$P$9,0) -> 0 | AA37: =SUM(D37:Z37) -> -1733
A38: =A37+1 -> 45690 | B38: =B37+AA38 -> 108.05 | C38: =IF(B38>B37,2,IF(B38=B37, 1,0)) -> 0 | D38: 0 | E38: =N("PAY-LM")+IF(WEEKDAY(A38)=Budget!$C$3,Budget!$B$3,0) -> 0 | F38: =N("Rent")-IF(DAY(A38)=Budget!$G$3,Budget!$F$3,0) -> 0 | G38: =N("Car")-IF(DAY(A38)=Budget!$G$4,Budget!$F$4+Budget!$H$4,0) -> -503.35 | H38: =N("Mom Rent")-IF(DAY(A38)=Budget!$G$5,Budget!$F$5,0) -> 0 | I38: =N("AT&T")-IF(DAY(A38)=Budget!$G$8,Budget!$F$8,0) -> 0 | J38: =N("GA Power")-IF(DAY(A38)=Budget!$G$9,Budget!$F$9,0) -> 0 | K38: =N("Haircut")-IF(DAY(A38)=Budget!$G$10,Budget!$F$10,0) -> 0 | L38: =N("Groceries")-IF(DAY(A38)=Budget!$G$6,Budget!$F$6,0) -> -300 | M38: =N("Savings")-IF(DAY(A38)=Budget!$G$7,Budget!$F$7,0) -> 0 | N38: =N("Car Insurance")-COUNTIF(Budget!$G$14, A38)*Budget!$F$14 -> 0 | O38: =N("Phone Bill")-COUNTIF(Budget!$G$15, A38)*Budget!$F$15 -> 0 | Q38: =N("Spotify")-IF(AND(DAY($A38)=Budget!$M$3, MONTH($A38)=Budget!$L$3),Budget!$K$3,0) -> 0 | R38: =N("Spotify")-IF(AND(DAY($A38)=Budget!$M$4, MONTH($A38)=Budget!$L$4),Budget!$K$4,0) -> 0 | S38: =N("Spotify")-IF(AND(DAY($A38)=Budget!$M$5, MONTH($A38)=Budget!$L$5),Budget!$K$5,0) -> 0 | T38: =N("Amazon Prime")-IF(DAY(A38)=Budget!$Q$3,Budget!$P$3,0) -> 0 | U38: =N("Audible")-IF(DAY(A38)=Budget!$Q$12,Budget!$P$12,0) -> 0 | V38: =N("Crunchyroll")-IF(DAY(A38)=Budget!$Q$5,Budget!$P$5,0) -> 0 | W38: =N("HBO Max")-IF(DAY(A38)=Budget!$Q$6,Budget!$P$6,0) -> 0 | X38: =N("Netflix")-IF(DAY(A38)=Budget!$Q$7,Budget!$P$7,0) -> 0 | Y38: =N("Spotify")-IF(DAY(A38)=Budget!$Q$8,Budget!$P$8,0) -> 0 | Z38: =N("Truebill")-IF(DAY(A38)=Budget!$Q$9,Budget!$P$9,0) -> 0 | AA38: =SUM(D38:Z38) -> -803.35
A39: =A38+1 -> 45691 | B39: =B38+AA39 -> 108.05 | C39: =IF(B39>B38,2,IF(B39=B38, 1,0)) -> 1 | D39: 0 | E39: =N("PAY-LM")+IF(WEEKDAY(A39)=Budget!$C$3,Budget!$B$3,0) -> 0 | F39: =N("Rent")-IF(DAY(A39)=Budget!$G$3,Budget!$F$3,0) -> 0 | G39: =N("Car")-IF(DAY(A39)=Budget!$G$4,Budget!$F$4+Budget!$H$4,0) -> 0 | H39: =N("Mom Rent")-IF(DAY(A39)=Budget!$G$5,Budget!$F$5,0) -> 0 | I39: =N("AT&T")-IF(DAY(A39)=Budget!$G$8,Budget!$F$8,0) -> 0 | J39: =N("GA Power")-IF(DAY(A39)=Budget!$G$9,Budget!$F$9,0) -> 0 | K39: =N("Haircut")-IF(DAY(A39)=Budget!$G$10,Budget!$F$10,0) -> 0 | L39: =N("Groceries")-IF(DAY(A39)=Budget!$G$6,Budget!$F$6,0) -> 0 | M39: =N("Savings")-IF(DAY(A39)=Budget!$G$7,Budget!$F$7,0) -> 0 | N39: =N("Car Insurance")-COUNTIF(Budget!$G$14, A39)*Budget!$F$14 -> 0 | O39: =N("Phone Bill")-COUNTIF(Budget!$G$15, A39)*Budget!$F$15 -> 0 | Q39: =N("Spotify")-IF(AND(DAY($A39)=Budget!$M$3, MONTH($A39)=Budget!$L$3),Budget!$K$3,0) -> 0 | R39: =N("Spotify")-IF(AND(DAY($A39)=Budget!$M$4, MONTH($A39)=Budget!$L$4),Budget!$K$4,0) -> 0 | S39: =N("Spotify")-IF(AND(DAY($A39)=Budget!$M$5, MONTH($A39)=Budget!$L$5),Budget!$K$5,0) -> 0 | T39: =N("Amazon Prime")-IF(DAY(A39)=Budget!$Q$3,Budget!$P$3,0) -> 0 | U39: =N("Audible")-IF(DAY(A39)=Budget!$Q$12,Budget!$P$12,0) -> 0 | V39: =N("Crunchyroll")-IF(DAY(A39)=Budget!$Q$5,Budget!$P$5,0) -> 0 | W39: =N("HBO Max")-IF(DAY(A39)=Budget!$Q$6,Budget!$P$6,0) -> 0 | X39: =N("Netflix")-IF(DAY(A39)=Budget!$Q$7,Budget!$P$7,0) -> 0 | Y39: =N("Spotify")-IF(DAY(A39)=Budget!$Q$8,Budget!$P$8,0) -> 0 | Z39: =N("Truebill")-IF(DAY(A39)=Budget!$Q$9,Budget!$P$9,0) -> 0 | AA39: =SUM(D39:Z39) -> 0
A40: =A39+1 -> 45692 | B40: =B39+AA40 -> 108.05 | C40: =IF(B40>B39,2,IF(B40=B39, 1,0)) -> 1 | D40: 0 | E40: =N("PAY-LM")+IF(WEEKDAY(A40)=Budget!$C$3,Budget!$B$3,0) -> 0 | F40: =N("Rent")-IF(DAY(A40)=Budget!$G$3,Budget!$F$3,0) -> 0 | G40: =N("Car")-IF(DAY(A40)=Budget!$G$4,Budget!$F$4+Budget!$H$4,0) -> 0 | H40: =N("Mom Rent")-IF(DAY(A40)=Budget!$G$5,Budget!$F$5,0) -> 0 | I40: =N("AT&T")-IF(DAY(A40)=Budget!$G$8,Budget!$F$8,0) -> 0 | J40: =N("GA Power")-IF(DAY(A40)=Budget!$G$9,Budget!$F$9,0) -> 0 | K40: =N("Haircut")-IF(DAY(A40)=Budget!$G$10,Budget!$F$10,0) -> 0 | L40: =N("Groceries")-IF(DAY(A40)=Budget!$G$6,Budget!$F$6,0) -> 0 | M40: =N("Savings")-IF(DAY(A40)=Budget!$G$7,Budget!$F$7,0) -> 0 | N40: =N("Car Insurance")-COUNTIF(Budget!$G$14, A40)*Budget!$F$14 -> 0 | O40: =N("Phone Bill")-COUNTIF(Budget!$G$15, A40)*Budget!$F$15 -> 0 | Q40: =N("Spotify")-IF(AND(DAY($A40)=Budget!$M$3, MONTH($A40)=Budget!$L$3),Budget!$K$3,0) -> 0 | R40: =N("Spotify")-IF(AND(DAY($A40)=Budget!$M$4, MONTH($A40)=Budget!$L$4),Budget!$K$4,0) -> 0 | S40: =N("Spotify")-IF(AND(DAY($A40)=Budget!$M$5, MONTH($A40)=Budget!$L$5),Budget!$K$5,0) -> 0 | T40: =N("Amazon Prime")-IF(DAY(A40)=Budget!$Q$3,Budget!$P$3,0) -> 0 | U40: =N("Audible")-IF(DAY(A40)=Budget!$Q$12,Budget!$P$12,0) -> 0 | V40: =N("Crunchyroll")-IF(DAY(A40)=Budget!$Q$5,Budget!$P$5,0) -> 0 | W40: =N("HBO Max")-IF(DAY(A40)=Budget!$Q$6,Budget!$P$6,0) -> 0 | X40: =N("Netflix")-IF(DAY(A40)=Budget!$Q$7,Budget!$P$7,0) -> 0 | Y40: =N("Spotify")-IF(DAY(A40)=Budget!$Q$8,Budget!$P$8,0) -> 0 | Z40: =N("Truebill")-IF(DAY(A40)=Budget!$Q$9,Budget!$P$9,0) -> 0 | AA40: =SUM(D40:Z40) -> 0
